Workbook

Sheet Lisez-moi
A1: Suivi des entraînements — ligne LC — Compétition — saison 2026-2027
B4: Un classeur par ligne d'eau
B5: Ce classeur suit une seule ligne d'eau, pour une seule saison. Le paramétrage du club vit dans « AA - Parametrage 2026-2027.xlsx » ; ce classeur en reçoit une copie de travail. Voir l'onglet Synchro.
B6: Une ligne d'eau a un seul support de saisie déclaré pour la saison : ce classeur, ou l'application. Jamais les deux.
B8: Quatre couleurs, quatre natures de cellule
B9: Blanc — saisie libre, à remplir à la main.
B10: Vert clair — saisie assistée par une liste déroulante : choisissez une valeur proposée.
B11: Gris clair — calculé par une formule de ce classeur : ça se met à jour tout seul, n'y touchez jamais.
B12: Bleu pâle — copié automatiquement depuis le classeur de Paramétrage à chaque synchronisation (onglets Referentiel, Personnes, Creneaux_Ref, Responsables, Qualifs_Securite) : une saisie ici serait silencieusement écrasée au prochain Synchro, sans message d'erreur.
B14: Sélectionner une personne
B15: Même principe que le classeur de paramétrage : une liste déroulante propose les personnes du club, triée par prénom. Tapez les premières lettres du prénom pour y aller plus vite, ou choisissez dans la liste. Le code numérique de l'onglet Personnes reste aussi accepté. Les colonnes suivantes affichent aussitôt l'identifiant, le nom et le prénom : un coup d'œil suffit à vérifier.
B17: Les listes se construisent toutes seules
B18: L'onglet Personnes porte l'ensemble du club, avec le groupe de niveau de chacun. Les membres de cette ligne y reçoivent automatiquement un code, de 1 à n. Les onglets Suivi_Objectifs, Suivi_Competences et Avis_Encadrants construisent leur liste d'apnéistes à partir de ce code : vous n'avez jamais de nom à recopier.
... B38: Version 1.1 — 2026-08-20.

Sheet Synchro
A1: Synchronisation avec le paramétrage du club
A2: Renseigné automatiquement par « sync_referentiel.py ». Ne pas modifier à la main.
A4: Information | B4: Valeur | C4: Remarque
A5: Ligne d'eau | B5: LC | C5: Groupe de niveau suivi par ce classeur
A6: Saison | B6: 2026-2027
A7: Classeur de paramétrage source | B7: AA - Parametrage 2026-2027.xlsx
A8: Version du paramétrage | B8: 1.3
A9: Date de la dernière synchronisation | B9: 2026-09-05 15:06 | C9: À relancer après toute modification du paramétrage
A10: Objectifs repris | B10: 10
A11: Compétences reprises | B11: 8
A12: Personnes reprises | B12: 97 | C12: Tout le club : un encadrant n'est pas nécessairement inscrit dans la ligne qu'il encadre
A13: Créneaux repris | B13: 1
A14: Responsables de ligne repris | B14: 0 | C14: Table datée : une ligne par changement en cours de saison
A16: Membres de la ligne, calculés en direct
A17: Apnéistes rattachés au groupe LC | B17: =COUNTIF(Personnes!$H$5:$H$154,"oui") -> 13 | C17: Déduit de la colonne « Groupe(s) » de l'onglet Personnes, sans intervention
A19: Pourquoi pas de lien Excel direct ?
A20: Une formule pointant vers un autre fichier dépend du chemin sur le disque. Elle casse dès que le classeur est déplacé, renommé, ouvert depuis un autre poste ou synchronisé par OneDrive.
A21: Le paramétrage est donc recopié ici, en lecture seule, par un script. C'est exactement ce que fera l'application plus tard.

Sheet Referentiel
A1: Référentiel de la ligne LC — Compétition
A2: Copie du paramétrage du club. Écrasé à chaque synchronisation : ne rien modifier ici.
A4: 1. OBJECTIFS DE PROGRESSION — maîtrise et acquisition
A5: ID | B5: Type | C5: Famille | D5: Intitulé | E5: Seuil de répétitions | F5: Intervalle max entre départs | G5: Critère de validation
A6: L4-M1 | B6: maîtrise | C6: DIST | D6: 125m dyn | G6: Pouvoir réaliser la distance sans contrainte particulière, régulièrement, sans incident. — critère qualitatif, non calculable.
A7: L4-M2 | B7: maîtrise | C7: SERIE_HC | D7: 4 x 50m départ 1' | G7: Pouvoir réaliser la distance sans contrainte particulière, régulièrement, sans incident. — critère qualitatif, non calculable.
A8: L4-M3 | B8: maîtrise | C8: STA_DYN | D8: 1'30 de STA + 75m | G8: Pouvoir réaliser la distance sans contrainte particulière, régulièrement, sans incident. — critère qualitatif, non calculable.
A9: L4-M4 | B9: maîtrise | C9: LENT | D9: 50m lent (2'30) | G9: Pouvoir réaliser la distance sans contrainte particulière, régulièrement, sans incident. — critère qualitatif, non calculable.
A10: L4-M5 | B10: maîtrise | C10: BRASSE | D10: 75m en brasse | G10: Pouvoir réaliser la distance sans contrainte particulière, régulièrement, sans incident. — critère qualitatif, non calculable.
A11: L4-A1 | B11: acquisition | C11: DIST | D11: 150m dyn | E11: 1 | G11: Pouvoir réaliser la distance ou l'exercice une fois de temps en temps en étant mis dans les meilleures conditions.
A12: L4-A2 | B12: acquisition | C12: SERIE_HC | D12: 4 x 50m départ 55'' | E12: 1 | G12: Pouvoir réaliser la distance ou l'exercice une fois de temps en temps en étant mis dans les meilleures conditions.
A13: L4-A3 | B13: acquisition | C13: STA_DYN | D13: 2' de STA + 75m | E13: 1 | G13: Pouvoir réaliser la distance ou l'exercice une fois de temps en temps en étant mis dans les meilleures conditions.
A14: L4-A4 | B14: acquisition | C14: LENT | D14: 50m lent (3') | E14: 1 | G14: Pouvoir réaliser la distance ou l'exercice une fois de temps en temps en étant mis dans les meilleures conditions.
A15: L4-A5 | B15: acquisition | C15: BRASSE | D15: 100m en brasse | E15: 1 | G15: Pouvoir réaliser la distance ou l'exercice une fois de temps en temps en étant mis dans les meilleures conditions.
A28: 2. COMPÉTENCES TECHNIQUES — niveau attendu en LC
A29: Code | B29: Libellé | C29: Niveau attendu | D29: Critère observable
A30: LEST | B30: Lestage | C30: expert | D30: Assiette horizontale tenue sans compensation musculaire ; flottabilité neutre en fin d'apnée.
A31: HYDRO | B31: Hydrodynamisme | C31: expert | D31: Position hydrodynamique conservée sur toute la distance ; aucun mouvement parasite.
A32: PALM_BI | B32: Palmage bi-palmes | C32: expert | D32: Ondulation propre, amplitude régulière, propulsion issue des hanches et non des cuisses.
A33: PALM_MONO | B33: Palmage monopalme | C33: acquis | D33: Ondulation continue tête-bassin-palme, bras en flèche tenus.
A34: VIRAGE | B34: Virage | C34: expert | D34: Virage fluide, sans perte de vitesse notable, sans apnée supplémentaire ; poussée d'au moins 10 m.
A35: VENTIL | B35: Ventilation | C35: expert | D35: Préparation ventilatoire abaissant la fréquence cardiaque, dernière inspiration maîtrisée, protocole de sécurité en sortie, récupération codée respectée.
A36: SAUV | B36: Sauvetage | C36: expert | D36: Sait repérer les signaux hypoxiques chez son binôme et conduire une remontée et un protocole de sauvetage.
A37: BRASSE | B37: Brasse DNF | C37: expert | D37: Coordination traction-glisse-ondulation, temps de glisse tenu, trajectoire rectiligne.
A52: 3. CRÉNEAUX DE LA LIGNE — copie du paramétrage
A53: ID | B53: Jour | C53: Heure début | D53: Heure fin | E53: Bassin | F53: Groupe de niveau | G53: Libellé (calculé) | H53: Encadrant (ID) | I53: Encadrant — nom | J53: Encadrant — prénom
A54: CR-SAM | B54: samedi | C54: 10h30 | D54: 12h00 | E54: B50 | F54: LC | H54: P045 | I54: SEGUI | J54: Danny
A66: 4. RESPONSABLE DE LIGNE — copie du paramétrage, table datée
A67: Date d'effet | B67: Personne (ID) | C67: Nom | D67: Prénom | E67: Commentaire
A79: 5. PERSONNES QUALIFIÉES SÉCURITÉ — copie du paramétrage, club entier
A80: Personne (ID) | B80: Nom | C80: Prénom

Sheet Personnes
A1: Personnes du club et effectif de la ligne
A2: Copie du référentiel du club. Le code de la colonne A est attribué automatiquement aux membres du groupe LC : c'est le raccourci de saisie.
A4: Code | B4: ID | C4: Nom | D4: Prénom | E4: Rôle déclaré | F4: Groupe(s) | G4: Objectif de la saison | H4: Membre de la ligne | I4: Séances suivies | J4: Séances tenues | K4: Taux de participation | L4: Code élève | M4: Code encadrant | N4: Libellé (calculé) | O4: Rang par prénom (calculé) | P4: Courriel
A5: =IF($H5="","",COUNTIF($H$5:$H5,"oui")) -> 1 | B5: P100 | C5: AUBERT | D5: Sebastien | E5: élève | F5: DNF / L4 / LC | H5: =IF($B5="","",IF(ISNUMBER(SEARCH("/LC/","/"&SUBSTITUTE($F5," / ","/")&"/")),"oui","")) -> oui | I5: =IF($H5="","",COUNTIF(Presences!$C$5:$C$504,$B5)) -> 0 | J5: =IF($H5="","",Tableau_de_bord!$B$5) -> 0 | K5: =IFERROR(IF($J5=0,"",$I5/$J5),"") | L5: =IF($H5<>"oui","",IF(OR($E5="élève",$E5="élève et encadrant"),COUNTIFS($H$5:$H5,"oui",$E$5:$E5,"élève")+COUNTIFS($H$5:$H5,"oui",$E$5:$E5,"élève et encadrant"),"")) -> 1 | M5: =IF($H5<>"oui","",IF(OR($E5="encadrant",$E5="élève et encadrant"),COUNTIFS($H$5:$H5,"oui",$E$5:$E5,"encadrant")+COUNTIFS($H$5:$H5,"oui",$E$5:$E5,"élève et encadrant"),"")) | N5: =IF($B5="","",TRIM(IF($D5="",$C5,$D5&" "&$C5))&" ["&$B5&"]") -> Sebastien AUBERT [P100] | O5: =IF($B5="","",COUNTIF(Personnes!$D$5:$D$154,"<"&$D5)+COUNTIF($D$5:$D5,$D5)) -> 82
A6: =IF($H6="","",COUNTIF($H$5:$H6,"oui")) -> 2 | B6: P101 | C6: BELHADJ KACEM | D6: Mohammed | E6: élève | F6: DNF / L4 / LC | H6: =IF($B6="","",IF(ISNUMBER(SEARCH("/LC/","/"&SUBSTITUTE($F6," / ","/")&"/")),"oui","")) -> oui | I6: =IF($H6="","",COUNTIF(Presences!$C$5:$C$504,$B6)) -> 0 | J6: =IF($H6="","",Tableau_de_bord!$B$5) -> 0 | K6: =IFERROR(IF($J6=0,"",$I6/$J6),"") | L6: =IF($H6<>"oui","",IF(OR($E6="élève",$E6="élève et encadrant"),COUNTIFS($H$5:$H6,"oui",$E$5:$E6,"élève")+COUNTIFS($H$5:$H6,"oui",$E$5:$E6,"élève et encadrant"),"")) -> 2 | M6: =IF($H6<>"oui","",IF(OR($E6="encadrant",$E6="élève et encadrant"),COUNTIFS($H$5:$H6,"oui",$E$5:$E6,"encadrant")+COUNTIFS($H$5:$H6,"oui",$E$5:$E6,"élève et encadrant"),"")) | N6: =IF($B6="","",TRIM(IF($D6="",$C6,$D6&" "&$C6))&" ["&$B6&"]") -> Mohammed BELHADJ KACEM [P101] | O6: =IF($B6="","",COUNTIF(Personnes!$D$5:$D$154,"<"&$D6)+COUNTIF($D$5:$D6,$D6)) -> 67
A7: =IF($H7="","",COUNTIF($H$5:$H7,"oui")) -> 3 | B7: P049 | C7: BOULANT | D7: Guillaume | E7: élève | F7: DNF / L4 / LC / STA | H7: =IF($B7="","",IF(ISNUMBER(SEARCH("/LC/","/"&SUBSTITUTE($F7," / ","/")&"/")),"oui","")) -> oui | I7: =IF($H7="","",COUNTIF(Presences!$C$5:$C$504,$B7)) -> 0 | J7: =IF($H7="","",Tableau_de_bord!$B$5) -> 0 | K7: =IFERROR(IF($J7=0,"",$I7/$J7),"") | L7: =IF($H7<>"oui","",IF(OR($E7="élève",$E7="élève et encadrant"),COUNTIFS($H$5:$H7,"oui",$E$5:$E7,"élève")+COUNTIFS($H$5:$H7,"oui",$E$5:$E7,"élève et encadrant"),"")) -> 3 | M7: =IF($H7<>"oui","",IF(OR($E7="encadrant",$E7="élève et encadrant"),COUNTIFS($H$5:$H7,"oui",$E$5:$E7,"encadrant")+COUNTIFS($H$5:$H7,"oui",$E$5:$E7,"élève et encadrant"),"")) | N7: =IF($B7="","",TRIM(IF($D7="",$C7,$D7&" "&$C7))&" ["&$B7&"]") -> Guillaume BOULANT [P049] | O7: =IF($B7="","",COUNTIF(Personnes!$D$5:$D$154,"<"&$D7)+COUNTIF($D$5:$D7,$D7)) -> 41 | P7: gboulant@gmail.com
A8: =IF($H8="","",COUNTIF($H$5:$H8,"oui")) -> 4 | B8: P057 | C8: COLIN DE VERDIERE | D8: Antoine | E8: élève | F8: DNF / L4 / LC | H8: =IF($B8="","",IF(ISNUMBER(SEARCH("/LC/","/"&SUBSTITUTE($F8," / ","/")&"/")),"oui","")) -> oui | I8: =IF($H8="","",COUNTIF(Presences!$C$5:$C$504,$B8)) -> 0 | J8: =IF($H8="","",Tableau_de_bord!$B$5) -> 0 | K8: =IFERROR(IF($J8=0,"",$I8/$J8),"") | L8: =IF($H8<>"oui","",IF(OR($E8="élève",$E8="élève et encadrant"),COUNTIFS($H$5:$H8,"oui",$E$5:$E8,"élève")+COUNTIFS($H$5:$H8,"oui",$E$5:$E8,"élève et encadrant"),"")) -> 4 | M8: =IF($H8<>"oui","",IF(OR($E8="encadrant",$E8="élève et encadrant"),COUNTIFS($H$5:$H8,"oui",$E$5:$E8,"encadrant")+COUNTIFS($H$5:$H8,"oui",$E$5:$E8,"élève et encadrant"),"")) | N8: =IF($B8="","",TRIM(IF($D8="",$C8,$D8&" "&$C8))&" ["&$B8&"]") -> Antoine COLIN DE VERDIERE [P057] | O8: =IF($B8="","",COUNTIF(Personnes!$D$5:$D$154,"<"&$D8)+COUNTIF($D$5:$D8,$D8)) -> 8 | P8: antoinecdv@gmail.com
A9: =IF($H9="","",COUNTIF($H$5:$H9,"oui")) -> 5 | B9: P063 | C9: COLLINET | D9: Sabine | E9: élève | F9: DNF / L4 / LC | H9: =IF($B9="","",IF(ISNUMBER(SEARCH("/LC/","/"&SUBSTITUTE($F9," / ","/")&"/")),"oui","")) -> oui | I9: =IF($H9="","",COUNTIF(Presences!$C$5:$C$504,$B9)) -> 0 | J9: =IF($H9="","",Tableau_de_bord!$B$5) -> 0 | K9: =IFERROR(IF($J9=0,"",$I9/$J9),"") | L9: =IF($H9<>"oui","",IF(OR($E9="élève",$E9="élève et encadrant"),COUNTIFS($H$5:$H9,"oui",$E$5:$E9,"élève")+COUNTIFS($H$5:$H9,"oui",$E$5:$E9,"élève et encadrant"),"")) -> 5 | M9: =IF($H9<>"oui","",IF(OR($E9="encadrant",$E9="élève et encadrant"),COUNTIFS($H$5:$H9,"oui",$E$5:$E9,"encadrant")+COUNTIFS($H$5:$H9,"oui",$E$5:$E9,"élève et encadrant"),"")) | N9: =IF($B9="","",TRIM(IF($D9="",$C9,$D9&" "&$C9))&" ["&$B9&"]") -> Sabine COLLINET [P063] | O9: =IF($B9="","",COUNTIF(Personnes!$D$5:$D$154,"<"&$D9)+COUNTIF($D$5:$D9,$D9)) -> 77 | P9: sabine.collinet@gmail.com
A10: =IF($H10="","",COUNTIF($H$5:$H10,"oui")) -> 6 | B10: P043 | C10: DUMONT | D10: Céline | E10: élève | F10: DNF / L4 / LC / STA | H10: =IF($B10="","",IF(ISNUMBER(SEARCH("/LC/","/"&SUBSTITUTE($F10," / ","/")&"/")),"oui","")) -> oui | I10: =IF($H10="","",COUNTIF(Presences!$C$5:$C$504,$B10)) -> 0 | J10: =IF($H10="","",Tableau_de_bord!$B$5) -> 0 | K10: =IFERROR(IF($J10=0,"",$I10/$J10),"") | L10: =IF($H10<>"oui","",IF(OR($E10="élève",$E10="élève et encadrant"),COUNTIFS($H$5:$H10,"oui",$E$5:$E10,"élève")+COUNTIFS($H$5:$H10,"oui",$E$5:$E10,"élève et encadrant"),"")) -> 6 | M10: =IF($H10<>"oui","",IF(OR($E10="encadrant",$E10="élève et encadrant"),COUNTIFS($H$5:$H10,"oui",$E$5:$E10,"encadrant")+COUNTIFS($H$5:$H10,"oui",$E$5:$E10,"élève et encadrant"),"")) | N10: =IF($B10="","",TRIM(IF($D10="",$C10,$D10&" "&$C10))&" ["&$B10&"]") -> Céline DUMONT [P043] | O10: =IF($B10="","",COUNTIF(Personnes!$D$5:$D$154,"<"&$D10)+COUNTIF($D$5:$D10,$D10)) -> 19 | P10: celibouteiller@gmail.com
A11: =IF($H11="","",COUNTIF($H$5:$H11,"oui")) -> 7 | B11: P102 | C11: DUSSAUD | D11: Sebastien | E11: élève | F11: DNF / L4 / LC | H11: =IF($B11="","",IF(ISNUMBER(SEARCH("/LC/","/"&SUBSTITUTE($F11," / ","/")&"/")),"oui","")) -> oui | I11: =IF($H11="","",COUNTIF(Presences!$C$5:$C$504,$B11)) -> 0 | J11: =IF($H11="","",Tableau_de_bord!$B$5) -> 0 | K11: =IFERROR(IF($J11=0,"",$I11/$J11),"") | L11: =IF($H11<>"oui","",IF(OR($E11="élève",$E11="élève et encadrant"),COUNTIFS($H$5:$H11,"oui",$E$5:$E11,"élève")+COUNTIFS($H$5:$H11,"oui",$E$5:$E11,"élève et encadrant"),"")) -> 7 | M11: =IF($H11<>"oui","",IF(OR($E11="encadrant",$E11="élève et encadrant"),COUNTIFS($H$5:$H11,"oui",$E$5:$E11,"encadrant")+COUNTIFS($H$5:$H11,"oui",$E$5:$E11,"élève et encadrant"),"")) | N11: =IF($B11="","",TRIM(IF($D11="",$C11,$D11&" "&$C11))&" ["&$B11&"]") -> Sebastien DUSSAUD [P102] | O11: =IF($B11="","",COUNTIF(Personnes!$D$5:$D$154,"<"&$D11)+COUNTIF($D$5:$D11,$D11)) -> 83
A12: =IF($H12="","",COUNTIF($H$5:$H12,"oui")) -> 8 | B12: P039 | C12: FREDON | D12: Philippe | E12: élève | F12: DNF / L4 / LC / STA | H12: =IF($B12="","",IF(ISNUMBER(SEARCH("/LC/","/"&SUBSTITUTE($F12," / ","/")&"/")),"oui","")) -> oui | I12: =IF($H12="","",COUNTIF(Presences!$C$5:$C$504,$B12)) -> 0 | J12: =IF($H12="","",Tableau_de_bord!$B$5) -> 0 | K12: =IFERROR(IF($J12=0,"",$I12/$J12),"") | L12: =IF($H12<>"oui","",IF(OR($E12="élève",$E12="élève et encadrant"),COUNTIFS($H$5:$H12,"oui",$E$5:$E12,"élève")+COUNTIFS($H$5:$H12,"oui",$E$5:$E12,"élève et encadrant"),"")) -> 8 | M12: =IF($H12<>"oui","",IF(OR($E12="encadrant",$E12="élève et encadrant"),COUNTIFS($H$5:$H12,"oui",$E$5:$E12,"encadrant")+COUNTIFS($H$5:$H12,"oui",$E$5:$E12,"élève et encadrant"),"")) | N12: =IF($B12="","",TRIM(IF($D12="",$C12,$D12&" "&$C12))&" ["&$B12&"]") -> Philippe FREDON [P039] | O12: =IF($B12="","",COUNTIF(Personnes!$D$5:$D$154,"<"&$D12)+COUNTIF($D$5:$D12,$D12)) -> 74 | P12: philippe.fredon@orange.fr
A13: =IF($H13="","",COUNTIF($H$5:$H13,"oui")) -> 9 | B13: P058 | C13: MAALAOUI | D13: Larbi | E13: élève | F13: DNF / L4 / LC | H13: =IF($B13="","",IF(ISNUMBER(SEARCH("/LC/","/"&SUBSTITUTE($F13," / ","/")&"/")),"oui","")) -> oui | I13: =IF($H13="","",COUNTIF(Presences!$C$5:$C$504,$B13)) -> 0 | J13: =IF($H13="","",Tableau_de_bord!$B$5) -> 0 | K13: =IFERROR(IF($J13=0,"",$I13/$J13),"") | L13: =IF($H13<>"oui","",IF(OR($E13="élève",$E13="élève et encadrant"),COUNTIFS($H$5:$H13,"oui",$E$5:$E13,"élève")+COUNTIFS($H$5:$H13,"oui",$E$5:$E13,"élève et encadrant"),"")) -> 9 | M13: =IF($H13<>"oui","",IF(OR($E13="encadrant",$E13="élève et encadrant"),COUNTIFS($H$5:$H13,"oui",$E$5:$E13,"encadrant")+COUNTIFS($H$5:$H13,"oui",$E$5:$E13,"élève et encadrant"),"")) | N13: =IF($B13="","",TRIM(IF($D13="",$C13,$D13&" "&$C13))&" ["&$B13&"]") -> Larbi MAALAOUI [P058] | O13: =IF($B13="","",COUNTIF(Personnes!$D$5:$D$154,"<"&$D13)+COUNTIF($D$5:$D13,$D13)) -> 53 | P13: lmaalaoui@yahoo.fr
A14: =IF($H14="","",COUNTIF($H$5:$H14,"oui")) -> 10 | B14: P103 | C14: NOURA | D14: Karim | E14: élève | F14: DNF / L4 / LC | H14: =IF($B14="","",IF(ISNUMBER(SEARCH("/LC/","/"&SUBSTITUTE($F14," / ","/")&"/")),"oui","")) -> oui | I14: =IF($H14="","",COUNTIF(Presences!$C$5:$C$504,$B14)) -> 0 | J14: =IF($H14="","",Tableau_de_bord!$B$5) -> 0 | K14: =IFERROR(IF($J14=0,"",$I14/$J14),"") | L14: =IF($H14<>"oui","",IF(OR($E14="élève",$E14="élève et encadrant"),COUNTIFS($H$5:$H14,"oui",$E$5:$E14,"élève")+COUNTIFS($H$5:$H14,"oui",$E$5:$E14,"élève et encadrant"),"")) -> 10 | M14: =IF($H14<>"oui","",IF(OR($E14="encadrant",$E14="élève et encadrant"),COUNTIFS($H$5:$H14,"oui",$E$5:$E14,"encadrant")+COUNTIFS($H$5:$H14,"oui",$E$5:$E14,"élève et encadrant"),"")) | N14: =IF($B14="","",TRIM(IF($D14="",$C14,$D14&" "&$C14))&" ["&$B14&"]") -> Karim NOURA [P103] | O14: =IF($B14="","",COUNTIF(Personnes!$D$5:$D$154,"<"&$D14)+COUNTIF($D$5:$D14,$D14)) -> 50
A15: =IF($H15="","",COUNTIF($H$5:$H15,"oui")) -> 11 | B15: P044 | C15: PASCAL | D15: Alain | E15: élève | F15: DNF / L4 / LC / STA | H15: =IF($B15="","",IF(ISNUMBER(SEARCH("/LC/","/"&SUBSTITUTE($F15," / ","/")&"/")),"oui","")) -> oui | I15: =IF($H15="","",COUNTIF(Presences!$C$5:$C$504,$B15)) -> 0 | J15: =IF($H15="","",Tableau_de_bord!$B$5) -> 0 | K15: =IFERROR(IF($J15=0,"",$I15/$J15),"") | L15: =IF($H15<>"oui","",IF(OR($E15="élève",$E15="élève et encadrant"),COUNTIFS($H$5:$H15,"oui",$E$5:$E15,"élève")+COUNTIFS($H$5:$H15,"oui",$E$5:$E15,"élève et encadrant"),"")) -> 11 | M15: =IF($H15<>"oui","",IF(OR($E15="encadrant",$E15="élève et encadrant"),COUNTIFS($H$5:$H15,"oui",$E$5:$E15,"encadrant")+COUNTIFS($H$5:$H15,"oui",$E$5:$E15,"élève et encadrant"),"")) | N15: =IF($B15="","",TRIM(IF($D15="",$C15,$D15&" "&$C15))&" ["&$B15&"]") -> Alain PASCAL [P044] | O15: =IF($B15="","",COUNTIF(Personnes!$D$5:$D$154,"<"&$D15)+COUNTIF($D$5:$D15,$D15)) -> 3 | P15: linux.apa@gmail.com
A16: =IF($H16="","",COUNTIF($H$5:$H16,"oui")) -> 12 | B16: P045 | C16: SEGUI | D16: Danny | E16: encadrant | F16: DNF / L4 / LC | H16: =IF($B16="","",IF(ISNUMBER(SEARCH("/LC/","/"&SUBSTITUTE($F16," / ","/")&"/")),"oui","")) -> oui | I16: =IF($H16="","",COUNTIF(Presences!$C$5:$C$504,$B16)) -> 0 | J16: =IF($H16="","",Tableau_de_bord!$B$5) -> 0 | K16: =IFERROR(IF($J16=0,"",$I16/$J16),"") | L16: =IF($H16<>"oui","",IF(OR($E16="élève",$E16="élève et encadrant"),COUNTIFS($H$5:$H16,"oui",$E$5:$E16,"élève")+COUNTIFS($H$5:$H16,"oui",$E$5:$E16,"élève et encadrant"),"")) | M16: =IF($H16<>"oui","",IF(OR($E16="encadrant",$E16="élève et encadrant"),COUNTIFS($H$5:$H16,"oui",$E$5:$E16,"encadrant")+COUNTIFS($H$5:$H16,"oui",$E$5:$E16,"élève et encadrant"),"")) -> 1 | N16: =IF($B16="","",TRIM(IF($D16="",$C16,$D16&" "&$C16))&" ["&$B16&"]") -> Danny SEGUI [P045] | O16: =IF($B16="","",COUNTIF(Personnes!$D$5:$D$154,"<"&$D16)+COUNTIF($D$5:$D16,$D16)) -> 27 | P16: d.segui@psm-ffessm.fr
A17: =IF($H17="","",COUNTIF($H$5:$H17,"oui")) -> 13 | B17: P045 | C17: SEGUI | D17: Danny | E17: élève | F17: DNF / L4 / LC | H17: =IF($B17="","",IF(ISNUMBER(SEARCH("/LC/","/"&SUBSTITUTE($F17," / ","/")&"/")),"oui","")) -> oui | I17: =IF($H17="","",COUNTIF(Presences!$C$5:$C$504,$B17)) -> 0 | J17: =IF($H17="","",Tableau_de_bord!$B$5) -> 0 | K17: =IFERROR(IF($J17=0,"",$I17/$J17),"") | L17: =IF($H17<>"oui","",IF(OR($E17="élève",$E17="élève et encadrant"),COUNTIFS($H$5:$H17,"oui",$E$5:$E17,"élève")+COUNTIFS($H$5:$H17,"oui",$E$5:$E17,"élève et encadrant"),"")) -> 12 | M17: =IF($H17<>"oui","",IF(OR($E17="encadrant",$E17="élève et encadrant"),COUNTIFS($H$5:$H17,"oui",$E$5:$E17,"encadrant")+COUNTIFS($H$5:$H17,"oui",$E$5:$E17,"élève et encadrant"),"")) | N17: =IF($B17="","",TRIM(IF($D17="",$C17,$D17&" "&$C17))&" ["&$B17&"]") -> Danny SEGUI [P045] | O17: =IF($B17="","",COUNTIF(Personnes!$D$5:$D$154,"<"&$D17)+COUNTIF($D$5:$D17,$D17)) -> 28 | P17: d.segui@psm-ffessm.fr
A18: =IF($H18="","",COUNTIF($H$5:$H18,"oui")) | B18: P053 | C18: BACHA | D18: Achour | F18: DNF / L4 / STA | H18: =IF($B18="","",IF(ISNUMBER(SEARCH("/LC/","/"&SUBSTITUTE($F18," / ","/")&"/")),"oui","")) | I18: =IF($H18="","",COUNTIF(Presences!$C$5:$C$504,$B18)) | J18: =IF($H18="","",Tableau_de_bord!$B$5) | K18: =IFERROR(IF($J18=0,"",$I18/$J18),"") | L18: =IF($H18<>"oui","",IF(OR($E18="élève",$E18="élève et encadrant"),COUNTIFS($H$5:$H18,"oui",$E$5:$E18,"élève")+COUNTIFS($H$5:$H18,"oui",$E$5:$E18,"élève et encadrant"),"")) | M18: =IF($H18<>"oui","",IF(OR($E18="encadrant",$E18="élève et encadrant"),COUNTIFS($H$5:$H18,"oui",$E$5:$E18,"encadrant")+COUNTIFS($H$5:$H18,"oui",$E$5:$E18,"élève et encadrant"),"")) | N18: =IF($B18="","",TRIM(IF($D18="",$C18,$D18&" "&$C18))&" ["&$B18&"]") -> Achour BACHA [P053] | O18: =IF($B18="","",COUNTIF(Personnes!$D$5:$D$154,"<"&$D18)+COUNTIF($D$5:$D18,$D18)) -> 1
A19: =IF($H19="","",COUNTIF($H$5:$H19,"oui")) | B19: P003 | C19: BARBIER | D19: Aurelien | F19: DNF / L3 / STA | H19: =IF($B19="","",IF(ISNUMBER(SEARCH("/LC/","/"&SUBSTITUTE($F19," / ","/")&"/")),"oui","")) | I19: =IF($H19="","",COUNTIF(Presences!$C$5:$C$504,$B19)) | J19: =IF($H19="","",Tableau_de_bord!$B$5) | K19: =IFERROR(IF($J19=0,"",$I19/$J19),"") | L19: =IF($H19<>"oui","",IF(OR($E19="élève",$E19="élève et encadrant"),COUNTIFS($H$5:$H19,"oui",$E$5:$E19,"élève")+COUNTIFS($H$5:$H19,"oui",$E$5:$E19,"élève et encadrant"),"")) | M19: =IF($H19<>"oui","",IF(OR($E19="encadrant",$E19="élève et encadrant"),COUNTIFS($H$5:$H19,"oui",$E$5:$E19,"encadrant")+COUNTIFS($H$5:$H19,"oui",$E$5:$E19,"élève et encadrant"),"")) | N19: =IF($B19="","",TRIM(IF($D19="",$C19,$D19&" "&$C19))&" ["&$B19&"]") -> Aurelien BARBIER [P003] | O19: =IF($B19="","",COUNTIF(Personnes!$D$5:$D$154,"<"&$D19)+COUNTIF($D$5:$D19,$D19)) -> 12
A20: =IF($H20="","",COUNTIF($H$5:$H20,"oui")) | B20: P076 | C20: BAUTISTA | D20: Mary | F20: DNF / L2 / STA | H20: =IF($B20="","",IF(ISNUMBER(SEARCH("/LC/","/"&SUBSTITUTE($F20," / ","/")&"/")),"oui","")) | I20: =IF($H20="","",COUNTIF(Presences!$C$5:$C$504,$B20)) | J20: =IF($H20="","",Tableau_de_bord!$B$5) | K20: =IFERROR(IF($J20=0,"",$I20/$J20),"") | L20: =IF($H20<>"oui","",IF(OR($E20="élève",$E20="élève et encadrant"),COUNTIFS($H$5:$H20,"oui",$E$5:$E20,"élève")+COUNTIFS($H$5:$H20,"oui",$E$5:$E20,"élève et encadrant"),"")) | M20: =IF($H20<>"oui","",IF(OR($E20="encadrant",$E20="élève et encadrant"),COUNTIFS($H$5:$H20,"oui",$E$5:$E20,"encadrant")+COUNTIFS($H$5:$H20,"oui",$E$5:$E20,"élève et encadrant"),"")) | N20: =IF($B20="","",TRIM(IF($D20="",$C20,$D20&" "&$C20))&" ["&$B20&"]") -> Mary BAUTISTA [P076] | O20: =IF($B20="","",COUNTIF(Personnes!$D$5:$D$154,"<"&$D20)+COUNTIF($D$5:$D20,$D20)) -> 63
A21: =IF($H21="","",COUNTIF($H$5:$H21,"oui")) | B21: P030 | C21: BEAUVALLET | D21: Dominique | F21: DNF / L1 / STA | H21: =IF($B21="","",IF(ISNUMBER(SEARCH("/LC/","/"&SUBSTITUTE($F21," / ","/")&"/")),"oui","")) | I21: =IF($H21="","",COUNTIF(Presences!$C$5:$C$504,$B21)) | J21: =IF($H21="","",Tableau_de_bord!$B$5) | K21: =IFERROR(IF($J21=0,"",$I21/$J21),"") | L21: =IF($H21<>"oui","",IF(OR($E21="élève",$E21="élève et encadrant"),COUNTIFS($H$5:$H21,"oui",$E$5:$E21,"élève")+COUNTIFS($H$5:$H21,"oui",$E$5:$E21,"élève et encadrant"),"")) | M21: =IF($H21<>"oui","",IF(OR($E21="encadrant",$E21="élève et encadrant"),COUNTIFS($H$5:$H21,"oui",$E$5:$E21,"encadrant")+COUNTIFS($H$5:$H21,"oui",$E$5:$E21,"élève et encadrant"),"")) | N21: =IF($B21="","",TRIM(IF($D21="",$C21,$D21&" "&$C21))&" ["&$B21&"]") -> Dominique BEAUVALLET [P030] | O21: =IF($B21="","",COUNTIF(Personnes!$D$5:$D$154,"<"&$D21)+COUNTIF($D$5:$D21,$D21)) -> 30 | P21: dombeauvallet@free.fr
A22: =IF($H22="","",COUNTIF($H$5:$H22,"oui")) | B22: P019 | C22: BECHARA | D22: Lionel | F22: DNF / L4 / STA | H22: =IF($B22="","",IF(ISNUMBER(SEARCH("/LC/","/"&SUBSTITUTE($F22," / ","/")&"/")),"oui","")) | I22: =IF($H22="","",COUNTIF(Presences!$C$5:$C$504,$B22)) | J22: =IF($H22="","",Tableau_de_bord!$B$5) | K22: =IFERROR(IF($J22=0,"",$I22/$J22),"") | L22: =IF($H22<>"oui","",IF(OR($E22="élève",$E22="élève et encadrant"),COUNTIFS($H$5:$H22,"oui",$E$5:$E22,"élève")+COUNTIFS($H$5:$H22,"oui",$E$5:$E22,"élève et encadrant"),"")) | M22: =IF($H22<>"oui","",IF(OR($E22="encadrant",$E22="élève et encadrant"),COUNTIFS($H$5:$H22,"oui",$E$5:$E22,"encadrant")+COUNTIFS($H$5:$H22,"oui",$E$5:$E22,"élève et encadrant"),"")) | N22: =IF($B22="","",TRIM(IF($D22="",$C22,$D22&" "&$C22))&" ["&$B22&"]") -> Lionel BECHARA [P019] | O22: =IF($B22="","",COUNTIF(Personnes!$D$5:$D$154,"<"&$D22)+COUNTIF($D$5:$D22,$D22)) -> 56
A23: =IF($H23="","",COUNTIF($H$5:$H23,"oui")) | B23: P077 | C23: BENDER | D23: Marc | F23: DNF / L2 / STA | H23: =IF($B23="","",IF(ISNUMBER(SEARCH("/LC/","/"&SUBSTITUTE($F23," / ","/")&"/")),"oui","")) | I23: =IF($H23="","",COUNTIF(Presences!$C$5:$C$504,$B23)) | J23: =IF($H23="","",Tableau_de_bord!$B$5) | K23: =IFERROR(IF($J23=0,"",$I23/$J23),"") | L23: =IF($H23<>"oui","",IF(OR($E23="élève",$E23="élève et encadrant"),COUNTIFS($H$5:$H23,"oui",$E$5:$E23,"élève")+COUNTIFS($H$5:$H23,"oui",$E$5:$E23,"élève et encadrant"),"")) | M23: =IF($H23<>"oui","",IF(OR($E23="encadrant",$E23="élève et encadrant"),COUNTIFS($H$5:$H23,"oui",$E$5:$E23,"encadrant")+COUNTIFS($H$5:$H23,"oui",$E$5:$E23,"élève et encadrant"),"")) | N23: =IF($B23="","",TRIM(IF($D23="",$C23,$D23&" "&$C23))&" ["&$B23&"]") -> Marc BENDER [P077] | O23: =IF($B23="","",COUNTIF(Personnes!$D$5:$D$154,"<"&$D23)+COUNTIF($D$5:$D23,$D23)) -> 59
A24: =IF($H24="","",COUNTIF($H$5:$H24,"oui")) | B24: P055 | C24: BENMANSOUR | D24: Ouafa | F24: DNF / L2 / STA | H24: =IF($B24="","",IF(ISNUMBER(SEARCH("/LC/","/"&SUBSTITUTE($F24," / ","/")&"/")),"oui","")) | I24: =IF($H24="","",COUNTIF(Presences!$C$5:$C$504,$B24)) | J24: =IF($H24="","",Tableau_de_bord!$B$5) | K24: =IFERROR(IF($J24=0,"",$I24/$J24),"") | L24: =IF($H24<>"oui","",IF(OR($E24="élève",$E24="élève et encadrant"),COUNTIFS($H$5:$H24,"oui",$E$5:$E24,"élève")+COUNTIFS($H$5:$H24,"oui",$E$5:$E24,"élève et encadrant"),"")) | M24: =IF($H24<>"oui","",IF(OR($E24="encadrant",$E24="élève et encadrant"),COUNTIFS($H$5:$H24,"oui",$E$5:$E24,"encadrant")+COUNTIFS($H$5:$H24,"oui",$E$5:$E24,"élève et encadrant"),"")) | N24: =IF($B24="","",TRIM(IF($D24="",$C24,$D24&" "&$C24))&" ["&$B24&"]") -> Ouafa BENMANSOUR [P055] | O24: =IF($B24="","",COUNTIF(Personnes!$D$5:$D$154,"<"&$D24)+COUNTIF($D$5:$D24,$D24)) -> 71 | P24: Amiwafa77@yahoo.fr
A25: =IF($H25="","",COUNTIF($H$5:$H25,"oui")) | B25: P035 | C25: BEYL | D25: Gabrielle | F25: DNF / L3 / L4 / STA | H25: =IF($B25="","",IF(ISNUMBER(SEARCH("/LC/","/"&SUBSTITUTE($F25," / ","/")&"/")),"oui","")) | I25: =IF($H25="","",COUNTIF(Presences!$C$5:$C$504,$B25)) | J25: =IF($H25="","",Tableau_de_bord!$B$5) | K25: =IFERROR(IF($J25=0,"",$I25/$J25),"") | L25: =IF($H25<>"oui","",IF(OR($E25="élève",$E25="élève et encadrant"),COUNTIFS($H$5:$H25,"oui",$E$5:$E25,"élève")+COUNTIFS($H$5:$H25,"oui",$E$5:$E25,"élève et encadrant"),"")) | M25: =IF($H25<>"oui","",IF(OR($E25="encadrant",$E25="élève et encadrant"),COUNTIFS($H$5:$H25,"oui",$E$5:$E25,"encadrant")+COUNTIFS($H$5:$H25,"oui",$E$5:$E25,"élève et encadrant"),"")) | N25: =IF($B25="","",TRIM(IF($D25="",$C25,$D25&" "&$C25))&" ["&$B25&"]") -> Gabrielle BEYL [P035] | O25: =IF($B25="","",COUNTIF(Personnes!$D$5:$D$154,"<"&$D25)+COUNTIF($D$5:$D25,$D25)) -> 39 | P25: g.beyl@outlook.fr
A26: =IF($H26="","",COUNTIF($H$5:$H26,"oui")) | B26: P078 | C26: BEZICOT | D26: Patrick | F26: DNF / L2 / STA | H26: =IF($B26="","",IF(ISNUMBER(SEARCH("/LC/","/"&SUBSTITUTE($F26," / ","/")&"/")),"oui","")) | I26: =IF($H26="","",COUNTIF(Presences!$C$5:$C$504,$B26)) | J26: =IF($H26="","",Tableau_de_bord!$B$5) | K26: =IFERROR(IF($J26=0,"",$I26/$J26),"") | L26: =IF($H26<>"oui","",IF(OR($E26="élève",$E26="élève et encadrant"),COUNTIFS($H$5:$H26,"oui",$E$5:$E26,"élève")+COUNTIFS($H$5:$H26,"oui",$E$5:$E26,"élève et encadrant"),"")) | M26: =IF($H26<>"oui","",IF(OR($E26="encadrant",$E26="élève et encadrant"),COUNTIFS($H$5:$H26,"oui",$E$5:$E26,"encadrant")+COUNTIFS($H$5:$H26,"oui",$E$5:$E26,"élève et encadrant"),"")) | N26: =IF($B26="","",TRIM(IF($D26="",$C26,$D26&" "&$C26))&" ["&$B26&"]") -> Patrick BEZICOT [P078] | O26: =IF($B26="","",COUNTIF(Personnes!$D$5:$D$154,"<"&$D26)+COUNTIF($D$5:$D26,$D26)) -> 72
A27: =IF($H27="","",COUNTIF($H$5:$H27,"oui")) | B27: P079 | C27: BIZON | D27: Christophe | F27: DNF / L2 / STA | H27: =IF($B27="","",IF(ISNUMBER(SEARCH("/LC/","/"&SUBSTITUTE($F27," / ","/")&"/")),"oui","")) | I27: =IF($H27="","",COUNTIF(Presences!$C$5:$C$504,$B27)) | J27: =IF($H27="","",Tableau_de_bord!$B$5) | K27: =IFERROR(IF($J27=0,"",$I27/$J27),"") | L27: =IF($H27<>"oui","",IF(OR($E27="élève",$E27="élève et encadrant"),COUNTIFS($H$5:$H27,"oui",$E$5:$E27,"élève")+COUNTIFS($H$5:$H27,"oui",$E$5:$E27,"élève et encadrant"),"")) | M27: =IF($H27<>"oui","",IF(OR($E27="encadrant",$E27="élève et encadrant"),COUNTIFS($H$5:$H27,"oui",$E$5:$E27,"encadrant")+COUNTIFS($H$5:$H27,"oui",$E$5:$E27,"élève et encadrant"),"")) | N27: =IF($B27="","",TRIM(IF($D27="",$C27,$D27&" "&$C27))&" ["&$B27&"]") -> Christophe BIZON [P079] | O27: =IF($B27="","",COUNTIF(Personnes!$D$5:$D$154,"<"&$D27)+COUNTIF($D$5:$D27,$D27)) -> 22
A28: =IF($H28="","",COUNTIF($H$5:$H28,"oui")) | B28: P060 | C28: BOUGEROL | D28: Bruno | F28: DNF / L2 / STA | H28: =IF($B28="","",IF(ISNUMBER(SEARCH("/LC/","/"&SUBSTITUTE($F28," / ","/")&"/")),"oui","")) | I28: =IF($H28="","",COUNTIF(Presences!$C$5:$C$504,$B28)) | J28: =IF($H28="","",Tableau_de_bord!$B$5) | K28: =IFERROR(IF($J28=0,"",$I28/$J28),"") | L28: =IF($H28<>"oui","",IF(OR($E28="élève",$E28="élève et encadrant"),COUNTIFS($H$5:$H28,"oui",$E$5:$E28,"élève")+COUNTIFS($H$5:$H28,"oui",$E$5:$E28,"élève et encadrant"),"")) | M28: =IF($H28<>"oui","",IF(OR($E28="encadrant",$E28="élève et encadrant"),COUNTIFS($H$5:$H28,"oui",$E$5:$E28,"encadrant")+COUNTIFS($H$5:$H28,"oui",$E$5:$E28,"élève et encadrant"),"")) | N28: =IF($B28="","",TRIM(IF($D28="",$C28,$D28&" "&$C28))&" ["&$B28&"]") -> Bruno BOUGEROL [P060] | O28: =IF($B28="","",COUNTIF(Personnes!$D$5:$D$154,"<"&$D28)+COUNTIF($D$5:$D28,$D28)) -> 17 | P28: b_bougerol@yahoo.fr
A29: =IF($H29="","",COUNTIF($H$5:$H29,"oui")) | B29: P068 | C29: BOUHAMMOU | D29: Salman | F29: DNF / L3 / STA | H29: =IF($B29="","",IF(ISNUMBER(SEARCH("/LC/","/"&SUBSTITUTE($F29," / ","/")&"/")),"oui","")) | I29: =IF($H29="","",COUNTIF(Presences!$C$5:$C$504,$B29)) | J29: =IF($H29="","",Tableau_de_bord!$B$5) | K29: =IFERROR(IF($J29=0,"",$I29/$J29),"") | L29: =IF($H29<>"oui","",IF(OR($E29="élève",$E29="élève et encadrant"),COUNTIFS($H$5:$H29,"oui",$E$5:$E29,"élève")+COUNTIFS($H$5:$H29,"oui",$E$5:$E29,"élève et encadrant"),"")) | M29: =IF($H29<>"oui","",IF(OR($E29="encadrant",$E29="élève et encadrant"),COUNTIFS($H$5:$H29,"oui",$E$5:$E29,"encadrant")+COUNTIFS($H$5:$H29,"oui",$E$5:$E29,"élève et encadrant"),"")) | N29: =IF($B29="","",TRIM(IF($D29="",$C29,$D29&" "&$C29))&" ["&$B29&"]") -> Salman BOUHAMMOU [P068] | O29: =IF($B29="","",COUNTIF(Personnes!$D$5:$D$154,"<"&$D29)+COUNTIF($D$5:$D29,$D29)) -> 78
A30: =IF($H30="","",COUNTIF($H$5:$H30,"oui")) | B30: P080 | C30: BRIAULT | D30: Beverly | F30: DNF / L2 / STA | H30: =IF($B30="","",IF(ISNUMBER(SEARCH("/LC/","/"&SUBSTITUTE($F30," / ","/")&"/")),"oui","")) | I30: =IF($H30="","",COUNTIF(Presences!$C$5:$C$504,$B30)) | J30: =IF($H30="","",Tableau_de_bord!$B$5) | K30: =IFERROR(IF($J30=0,"",$I30/$J30),"") | L30: =IF($H30<>"oui","",IF(OR($E30="élève",$E30="élève et encadrant"),COUNTIFS($H$5:$H30,"oui",$E$5:$E30,"élève")+COUNTIFS($H$5:$H30,"oui",$E$5:$E30,"élève et encadrant"),"")) | M30: =IF($H30<>"oui","",IF(OR($E30="encadrant",$E30="élève et encadrant"),COUNTIFS($H$5:$H30,"oui",$E$5:$E30,"encadrant")+COUNTIFS($H$5:$H30,"oui",$E$5:$E30,"élève et encadrant"),"")) | N30: =IF($B30="","",TRIM(IF($D30="",$C30,$D30&" "&$C30))&" ["&$B30&"]") -> Beverly BRIAULT [P080] | O30: =IF($B30="","",COUNTIF(Personnes!$D$5:$D$154,"<"&$D30)+COUNTIF($D$5:$D30,$D30)) -> 16
A31: =IF($H31="","",COUNTIF($H$5:$H31,"oui")) | B31: P056 | C31: BRIDENNE | D31: Philippe | F31: DNF / L2 / STA | H31: =IF($B31="","",IF(ISNUMBER(SEARCH("/LC/","/"&SUBSTITUTE($F31," / ","/")&"/")),"oui","")) | I31: =IF($H31="","",COUNTIF(Presences!$C$5:$C$504,$B31)) | J31: =IF($H31="","",Tableau_de_bord!$B$5) | K31: =IFERROR(IF($J31=0,"",$I31/$J31),"") | L31: =IF($H31<>"oui","",IF(OR($E31="élève",$E31="élève et encadrant"),COUNTIFS($H$5:$H31,"oui",$E$5:$E31,"élève")+COUNTIFS($H$5:$H31,"oui",$E$5:$E31,"élève et encadrant"),"")) | M31: =IF($H31<>"oui","",IF(OR($E31="encadrant",$E31="élève et encadrant"),COUNTIFS($H$5:$H31,"oui",$E$5:$E31,"encadrant")+COUNTIFS($H$5:$H31,"oui",$E$5:$E31,"élève et encadrant"),"")) | N31: =IF($B31="","",TRIM(IF($D31="",$C31,$D31&" "&$C31))&" ["&$B31&"]") -> Philippe BRIDENNE [P056] | O31: =IF($B31="","",COUNTIF(Personnes!$D$5:$D$154,"<"&$D31)+COUNTIF($D$5:$D31,$D31)) -> 75 | P31: philippe.bridenne@gmail.com
A32: =IF($H32="","",COUNTIF($H$5:$H32,"oui")) | B32: P081 | C32: CATHALA | D32: Virginie | F32: DNF / L2 / STA | H32: =IF($B32="","",IF(ISNUMBER(SEARCH("/LC/","/"&SUBSTITUTE($F32," / ","/")&"/")),"oui","")) | I32: =IF($H32="","",COUNTIF(Presences!$C$5:$C$504,$B32)) | J32: =IF($H32="","",Tableau_de_bord!$B$5) | K32: =IFERROR(IF($J32=0,"",$I32/$J32),"") | L32: =IF($H32<>"oui","",IF(OR($E32="élève",$E32="élève et encadrant"),COUNTIFS($H$5:$H32,"oui",$E$5:$E32,"élève")+COUNTIFS($H$5:$H32,"oui",$E$5:$E32,"élève et encadrant"),"")) | M32: =IF($H32<>"oui","",IF(OR($E32="encadrant",$E32="élève et encadrant"),COUNTIFS($H$5:$H32,"oui",$E$5:$E32,"encadrant")+COUNTIFS($H$5:$H32,"oui",$E$5:$E32,"élève et encadrant"),"")) | N32: =IF($B32="","",TRIM(IF($D32="",$C32,$D32&" "&$C32))&" ["&$B32&"]") -> Virginie CATHALA [P081] | O32: =IF($B32="","",COUNTIF(Personnes!$D$5:$D$154,"<"&$D32)+COUNTIF($D$5:$D32,$D32)) -> 96
A33: =IF($H33="","",COUNTIF($H$5:$H33,"oui")) | B33: P069 | C33: CAVATORE | D33: Magali | F33: DNF / L3 / STA | H33: =IF($B33="","",IF(ISNUMBER(SEARCH("/LC/","/"&SUBSTITUTE($F33," / ","/")&"/")),"oui","")) | I33: =IF($H33="","",COUNTIF(Presences!$C$5:$C$504,$B33)) | J33: =IF($H33="","",Tableau_de_bord!$B$5) | K33: =IFERROR(IF($J33=0,"",$I33/$J33),"") | L33: =IF($H33<>"oui","",IF(OR($E33="élève",$E33="élève et encadrant"),COUNTIFS($H$5:$H33,"oui",$E$5:$E33,"élève")+COUNTIFS($H$5:$H33,"oui",$E$5:$E33,"élève et encadrant"),"")) | M33: =IF($H33<>"oui","",IF(OR($E33="encadrant",$E33="élève et encadrant"),COUNTIFS($H$5:$H33,"oui",$E$5:$E33,"encadrant")+COUNTIFS($H$5:$H33,"oui",$E$5:$E33,"élève et encadrant"),"")) | N33: =IF($B33="","",TRIM(IF($D33="",$C33,$D33&" "&$C33))&" ["&$B33&"]") -> Magali CAVATORE [P069] | O33: =IF($B33="","",COUNTIF(Personnes!$D$5:$D$154,"<"&$D33)+COUNTIF($D$5:$D33,$D33)) -> 58
A34: =IF($H34="","",COUNTIF($H$5:$H34,"oui")) | B34: P097 | C34: CHABERNAUD | D34: Christophe | F34: DNF / L4 / STA | H34: =IF($B34="","",IF(ISNUMBER(SEARCH("/LC/","/"&SUBSTITUTE($F34," / ","/")&"/")),"oui","")) | I34: =IF($H34="","",COUNTIF(Presences!$C$5:$C$504,$B34)) | J34: =IF($H34="","",Tableau_de_bord!$B$5) | K34: =IFERROR(IF($J34=0,"",$I34/$J34),"") | L34: =IF($H34<>"oui","",IF(OR($E34="élève",$E34="élève et encadrant"),COUNTIFS($H$5:$H34,"oui",$E$5:$E34,"élève")+COUNTIFS($H$5:$H34,"oui",$E$5:$E34,"élève et encadrant"),"")) | M34: =IF($H34<>"oui","",IF(OR($E34="encadrant",$E34="élève et encadrant"),COUNTIFS($H$5:$H34,"oui",$E$5:$E34,"encadrant")+COUNTIFS($H$5:$H34,"oui",$E$5:$E34,"élève et encadrant"),"")) | N34: =IF($B34="","",TRIM(IF($D34="",$C34,$D34&" "&$C34))&" ["&$B34&"]") -> Christophe CHABERNAUD [P097] | O34: =IF($B34="","",COUNTIF(Personnes!$D$5:$D$154,"<"&$D34)+COUNTIF($D$5:$D34,$D34)) -> 23
A35: =IF($H35="","",COUNTIF($H$5:$H35,"oui")) | B35: P031 | C35: CHARDONNET | D35: Victorinne | F35: DNF / L1 / L2 / STA | H35: =IF($B35="","",IF(ISNUMBER(SEARCH("/LC/","/"&SUBSTITUTE($F35," / ","/")&"/")),"oui","")) | I35: =IF($H35="","",COUNTIF(Presences!$C$5:$C$504,$B35)) | J35: =IF($H35="","",Tableau_de_bord!$B$5) | K35: =IFERROR(IF($J35=0,"",$I35/$J35),"") | L35: =IF($H35<>"oui","",IF(OR($E35="élève",$E35="élève et encadrant"),COUNTIFS($H$5:$H35,"oui",$E$5:$E35,"élève")+COUNTIFS($H$5:$H35,"oui",$E$5:$E35,"élève et encadrant"),"")) | M35: =IF($H35<>"oui","",IF(OR($E35="encadrant",$E35="élève et encadrant"),COUNTIFS($H$5:$H35,"oui",$E$5:$E35,"encadrant")+COUNTIFS($H$5:$H35,"oui",$E$5:$E35,"élève et encadrant"),"")) | N35: =IF($B35="","",TRIM(IF($D35="",$C35,$D35&" "&$C35))&" ["&$B35&"]") -> Victorinne CHARDONNET [P031] | O35: =IF($B35="","",COUNTIF(Personnes!$D$5:$D$154,"<"&$D35)+COUNTIF($D$5:$D35,$D35)) -> 93 | P35: chardonnetvictorine@gmail.com
A36: =IF($H36="","",COUNTIF($H$5:$H36,"oui")) | B36: P022 | C36: CHIARAMONTE | D36: Matthieu | F36: DNF / L3 / STA | H36: =IF($B36="","",IF(ISNUMBER(SEARCH("/LC/","/"&SUBSTITUTE($F36," / ","/")&"/")),"oui","")) | I36: =IF($H36="","",COUNTIF(Presences!$C$5:$C$504,$B36)) | J36: =IF($H36="","",Tableau_de_bord!$B$5) | K36: =IFERROR(IF($J36=0,"",$I36/$J36),"") | L36: =IF($H36<>"oui","",IF(OR($E36="élève",$E36="élève et encadrant"),COUNTIFS($H$5:$H36,"oui",$E$5:$E36,"élève")+COUNTIFS($H$5:$H36,"oui",$E$5:$E36,"élève et encadrant"),"")) | M36: =IF($H36<>"oui","",IF(OR($E36="encadrant",$E36="élève et encadrant"),COUNTIFS($H$5:$H36,"oui",$E$5:$E36,"encadrant")+COUNTIFS($H$5:$H36,"oui",$E$5:$E36,"élève et encadrant"),"")) | N36: =IF($B36="","",TRIM(IF($D36="",$C36,$D36&" "&$C36))&" ["&$B36&"]") -> Matthieu CHIARAMONTE [P022] | O36: =IF($B36="","",COUNTIF(Personnes!$D$5:$D$154,"<"&$D36)+COUNTIF($D$5:$D36,$D36)) -> 64
A37: =IF($H37="","",COUNTIF($H$5:$H37,"oui")) | B37: P082 | C37: CODAZZO | D37: Franco | F37: DNF / L2 / STA | H37: =IF($B37="","",IF(ISNUMBER(SEARCH("/LC/","/"&SUBSTITUTE($F37," / ","/")&"/")),"oui","")) | I37: =IF($H37="","",COUNTIF(Presences!$C$5:$C$504,$B37)) | J37: =IF($H37="","",Tableau_de_bord!$B$5) | K37: =IFERROR(IF($J37=0,"",$I37/$J37),"") | L37: =IF($H37<>"oui","",IF(OR($E37="élève",$E37="élève et encadrant"),COUNTIFS($H$5:$H37,"oui",$E$5:$E37,"élève")+COUNTIFS($H$5:$H37,"oui",$E$5:$E37,"élève et encadrant"),"")) | M37: =IF($H37<>"oui","",IF(OR($E37="encadrant",$E37="élève et encadrant"),COUNTIFS($H$5:$H37,"oui",$E$5:$E37,"encadrant")+COUNTIFS($H$5:$H37,"oui",$E$5:$E37,"élève et encadrant"),"")) | N37: =IF($B37="","",TRIM(IF($D37="",$C37,$D37&" "&$C37))&" ["&$B37&"]") -> Franco CODAZZO [P082] | O37: =IF($B37="","",COUNTIF(Personnes!$D$5:$D$154,"<"&$D37)+COUNTIF($D$5:$D37,$D37)) -> 36
A38: =IF($H38="","",COUNTIF($H$5:$H38,"oui")) | B38: P006 | C38: COLIN DE VERDIERE | D38: Caroline | F38: DNF / L3 / STA | H38: =IF($B38="","",IF(ISNUMBER(SEARCH("/LC/","/"&SUBSTITUTE($F38," / ","/")&"/")),"oui","")) | I38: =IF($H38="","",COUNTIF(Presences!$C$5:$C$504,$B38)) | J38: =IF($H38="","",Tableau_de_bord!$B$5) | K38: =IFERROR(IF($J38=0,"",$I38/$J38),"") | L38: =IF($H38<>"oui","",IF(OR($E38="élève",$E38="élève et encadrant"),COUNTIFS($H$5:$H38,"oui",$E$5:$E38,"élève")+COUNTIFS($H$5:$H38,"oui",$E$5:$E38,"élève et encadrant"),"")) | M38: =IF($H38<>"oui","",IF(OR($E38="encadrant",$E38="élève et encadrant"),COUNTIFS($H$5:$H38,"oui",$E$5:$E38,"encadrant")+COUNTIFS($H$5:$H38,"oui",$E$5:$E38,"élève et encadrant"),"")) | N38: =IF($B38="","",TRIM(IF($D38="",$C38,$D38&" "&$C38))&" ["&$B38&"]") -> Caroline COLIN DE VERDIERE [P006] | O38: =IF($B38="","",COUNTIF(Personnes!$D$5:$D$154,"<"&$D38)+COUNTIF($D$5:$D38,$D38)) -> 18 | P38: treso.apneeattitude@outlook.com
A39: =IF($H39="","",COUNTIF($H$5:$H39,"oui")) | B39: P011 | C39: COLIN DE VERDIERE | D39: Etienne | F39: DNF / L3 / STA | H39: =IF($B39="","",IF(ISNUMBER(SEARCH("/LC/","/"&SUBSTITUTE($F39," / ","/")&"/")),"oui","")) | I39: =IF($H39="","",COUNTIF(Presences!$C$5:$C$504,$B39)) | J39: =IF($H39="","",Tableau_de_bord!$B$5) | K39: =IFERROR(IF($J39=0,"",$I39/$J39),"") | L39: =IF($H39<>"oui","",IF(OR($E39="élève",$E39="élève et encadrant"),COUNTIFS($H$5:$H39,"oui",$E$5:$E39,"élève")+COUNTIFS($H$5:$H39,"oui",$E$5:$E39,"élève et encadrant"),"")) | M39: =IF($H39<>"oui","",IF(OR($E39="encadrant",$E39="élève et encadrant"),COUNTIFS($H$5:$H39,"oui",$E$5:$E39,"encadrant")+COUNTIFS($H$5:$H39,"oui",$E$5:$E39,"élève et encadrant"),"")) | N39: =IF($B39="","",TRIM(IF($D39="",$C39,$D39&" "&$C39))&" ["&$B39&"]") -> Etienne COLIN DE VERDIERE [P011] | O39: =IF($B39="","",COUNTIF(Personnes!$D$5:$D$154,"<"&$D39)+COUNTIF($D$5:$D39,$D39)) -> 33 | P39: e.cdv@free.fr
A40: =IF($H40="","",COUNTIF($H$5:$H40,"oui")) | B40: P083 | C40: CORNET-VERNET | D40: Sandra | F40: DNF / L2 / STA | H40: =IF($B40="","",IF(ISNUMBER(SEARCH("/LC/","/"&SUBSTITUTE($F40," / ","/")&"/")),"oui","")) | I40: =IF($H40="","",COUNTIF(Presences!$C$5:$C$504,$B40)) | J40: =IF($H40="","",Tableau_de_bord!$B$5) | K40: =IFERROR(IF($J40=0,"",$I40/$J40),"") | L40: =IF($H40<>"oui","",IF(OR($E40="élève",$E40="élève et encadrant"),COUNTIFS($H$5:$H40,"oui",$E$5:$E40,"élève")+COUNTIFS($H$5:$H40,"oui",$E$5:$E40,"élève et encadrant"),"")) | M40: =IF($H40<>"oui","",IF(OR($E40="encadrant",$E40="élève et encadrant"),COUNTIFS($H$5:$H40,"oui",$E$5:$E40,"encadrant")+COUNTIFS($H$5:$H40,"oui",$E$5:$E40,"élève et encadrant"),"")) | N40: =IF($B40="","",TRIM(IF($D40="",$C40,$D40&" "&$C40))&" ["&$B40&"]") -> Sandra CORNET-VERNET [P083] | O40: =IF($B40="","",COUNTIF(Personnes!$D$5:$D$154,"<"&$D40)+COUNTIF($D$5:$D40,$D40)) -> 80
A41: =IF($H41="","",COUNTIF($H$5:$H41,"oui")) | B41: P084 | C41: COSSAIS | D41: Monia | F41: DNF / L2 / STA | H41: =IF($B41="","",IF(ISNUMBER(SEARCH("/LC/","/"&SUBSTITUTE($F41," / ","/")&"/")),"oui","")) | I41: =IF($H41="","",COUNTIF(Presences!$C$5:$C$504,$B41)) | J41: =IF($H41="","",Tableau_de_bord!$B$5) | K41: =IFERROR(IF($J41=0,"",$I41/$J41),"") | L41: =IF($H41<>"oui","",IF(OR($E41="élève",$E41="élève et encadrant"),COUNTIFS($H$5:$H41,"oui",$E$5:$E41,"élève")+COUNTIFS($H$5:$H41,"oui",$E$5:$E41,"élève et encadrant"),"")) | M41: =IF($H41<>"oui","",IF(OR($E41="encadrant",$E41="élève et encadrant"),COUNTIFS($H$5:$H41,"oui",$E$5:$E41,"encadrant")+COUNTIFS($H$5:$H41,"oui",$E$5:$E41,"élève et encadrant"),"")) | N41: =IF($B41="","",TRIM(IF($D41="",$C41,$D41&" "&$C41))&" ["&$B41&"]") -> Monia COSSAIS [P084] | O41: =IF($B41="","",COUNTIF(Personnes!$D$5:$D$154,"<"&$D41)+COUNTIF($D$5:$D41,$D41)) -> 68
...

Sheet Calendrier
A1: Calendrier des séances — ligne LC — Compétition
A2: Choisissez le créneau : jour, bassin et groupe se remplissent seuls. Le responsable de ligne est déduit de l'onglet Responsables.
A4: ID séance | B4: Date | C4: Jour | D4: Créneau | E4: Créneau (ID) | F4: Bassin | G4: Groupe | H4: Nature | I4: Statut | J4: Directeur de bassin — début du nom | K4: DP (ID) | L4: DP — nom | M4: DP — prénom | N4: Responsable remplaçant — début du nom | O4: Responsable (ID) | P4: Resp. — nom | Q4: Resp. — prénom | R4: Plan de séance (texte ou lien) | S4: Commentaire | T4: Nb de présents | U4: Contrôle
A5: =IF($B5="","","S"&TEXT(COUNTIF($B$5:$B5,"<>"),"000")&" — "&TEXT(DAY($B5),"00")&"/"&TEXT(MONTH($B5),"00")&"/"&YEAR($B5)&" ("&$C5&")") -> S001 — 12/09/2026 (samedi) | B5: 46277 | C5: =IF($B5="","",IFERROR(INDEX(Listes!$A$2:$A$8,WEEKDAY($B5,2)),"")) -> samedi | D5: CR-SAM — samedi 10h30-12h00 · B50 [CR-SAM] | E5: =IFERROR(MID($D5,FIND("[",$D5)+1,FIND("]",$D5)-FIND("[",$D5)-1),"") -> CR-SAM | F5: =IFERROR(IF($E5="","",INDEX(Referentiel!$E$54:$E$63,MATCH($E5,Referentiel!$A$54:$A$63,0))&""),"") -> B50 | G5: =IFERROR(IF($E5="","",INDEX(Referentiel!$F$54:$F$63,MATCH($E5,Referentiel!$A$54:$A$63,0))&""),"") -> LC | I5: planifiée | K5: =IF($J5="","",IFERROR(IF(ISNUMBER(FIND("[",$J5)),MID($J5,FIND("[",$J5)+1,FIND("]",$J5)-FIND("[",$J5)-1),IF(ISNUMBER($J5),INDEX(Personnes!$B$5:$B$154,MATCH($J5,Personnes!$A$5:$A$154,0)),IFERROR(INDEX(Personnes!$B$5:$B$154,MATCH($J5&"*",Personnes!$C$5:$C$154,0)),INDEX(Personnes!$B$5:$B$154,MATCH($J5&"*",Personnes!$D$5:$D$154,0))))),"")) | L5: =IFERROR(INDEX(Personnes!$C$5:$C$154,MATCH($K5,Personnes!$B$5:$B$154,0))&"","") | M5: =IFERROR(INDEX(Personnes!$D$5:$D$154,MATCH($K5,Personnes!$B$5:$B$154,0))&"","") | O5: =IF($N5<>"",IF($N5="","",IFERROR(IF(ISNUMBER(FIND("[",$N5)),MID($N5,FIND("[",$N5)+1,FIND("]",$N5)-FIND("[",$N5)-1),IF(ISNUMBER($N5),INDEX(Personnes!$B$5:$B$154,MATCH($N5,Personnes!$A$5:$A$154,0)),IFERROR(INDEX(Personnes!$B$5:$B$154,MATCH($N5&"*",Personnes!$C$5:$C$154,0)),INDEX(Personnes!$B$5:$B$154,MATCH($N5&"*",Personnes!$D$5:$D$154,0))))),"")),IF($E5="","",IFERROR(INDEX(Referentiel!$H$54:$H$63,MATCH($E5,Referentiel!$A$54:$A$63,0)),""))) -> P045 | P5: =IFERROR(INDEX(Personnes!$C$5:$C$154,MATCH($O5,Personnes!$B$5:$B$154,0))&"","") -> SEGUI | Q5: =IFERROR(INDEX(Personnes!$D$5:$D$154,MATCH($O5,Personnes!$B$5:$B$154,0))&"","") -> Danny | T5: =IF($A5="","",COUNTIFS(Presences!$A$5:$A$504,$A5,Presences!$C$5:$C$504,"<>")) -> 0 | U5: =IF($A5="","",IF(AND($J5<>"",$K5=""),"DP non reconnu",IF(AND($K5<>"",COUNTIF(Referentiel!$A$81:$A$110,$K5)=0),"DP sans qualification Sécurité valide",IF(AND($N5<>"",$O5=""),"responsable non reconnu",IF(AND($G5<>"",$G5<>"LC"),"créneau rattaché à un autre groupe",IF($I5<>"tenue","",IF(OR($K5="",$O5=""),"couverture incomplète","ok")))))))
A6: =IF($B6="","","S"&TEXT(COUNTIF($B$5:$B6,"<>"),"000")&" — "&TEXT(DAY($B6),"00")&"/"&TEXT(MONTH($B6),"00")&"/"&YEAR($B6)&" ("&$C6&")") -> S002 — 19/09/2026 (samedi) | B6: 46284 | C6: =IF($B6="","",IFERROR(INDEX(Listes!$A$2:$A$8,WEEKDAY($B6,2)),"")) -> samedi | D6: CR-SAM — samedi 10h30-12h00 · B50 [CR-SAM] | E6: =IFERROR(MID($D6,FIND("[",$D6)+1,FIND("]",$D6)-FIND("[",$D6)-1),"") -> CR-SAM | F6: =IFERROR(IF($E6="","",INDEX(Referentiel!$E$54:$E$63,MATCH($E6,Referentiel!$A$54:$A$63,0))&""),"") -> B50 | G6: =IFERROR(IF($E6="","",INDEX(Referentiel!$F$54:$F$63,MATCH($E6,Referentiel!$A$54:$A$63,0))&""),"") -> LC | I6: planifiée | K6: =IF($J6="","",IFERROR(IF(ISNUMBER(FIND("[",$J6)),MID($J6,FIND("[",$J6)+1,FIND("]",$J6)-FIND("[",$J6)-1),IF(ISNUMBER($J6),INDEX(Personnes!$B$5:$B$154,MATCH($J6,Personnes!$A$5:$A$154,0)),IFERROR(INDEX(Personnes!$B$5:$B$154,MATCH($J6&"*",Personnes!$C$5:$C$154,0)),INDEX(Personnes!$B$5:$B$154,MATCH($J6&"*",Personnes!$D$5:$D$154,0))))),"")) | L6: =IFERROR(INDEX(Personnes!$C$5:$C$154,MATCH($K6,Personnes!$B$5:$B$154,0))&"","") | M6: =IFERROR(INDEX(Personnes!$D$5:$D$154,MATCH($K6,Personnes!$B$5:$B$154,0))&"","") | O6: =IF($N6<>"",IF($N6="","",IFERROR(IF(ISNUMBER(FIND("[",$N6)),MID($N6,FIND("[",$N6)+1,FIND("]",$N6)-FIND("[",$N6)-1),IF(ISNUMBER($N6),INDEX(Personnes!$B$5:$B$154,MATCH($N6,Personnes!$A$5:$A$154,0)),IFERROR(INDEX(Personnes!$B$5:$B$154,MATCH($N6&"*",Personnes!$C$5:$C$154,0)),INDEX(Personnes!$B$5:$B$154,MATCH($N6&"*",Personnes!$D$5:$D$154,0))))),"")),IF($E6="","",IFERROR(INDEX(Referentiel!$H$54:$H$63,MATCH($E6,Referentiel!$A$54:$A$63,0)),""))) -> P045 | P6: =IFERROR(INDEX(Personnes!$C$5:$C$154,MATCH($O6,Personnes!$B$5:$B$154,0))&"","") -> SEGUI | Q6: =IFERROR(INDEX(Personnes!$D$5:$D$154,MATCH($O6,Personnes!$B$5:$B$154,0))&"","") -> Danny | T6: =IF($A6="","",COUNTIFS(Presences!$A$5:$A$504,$A6,Presences!$C$5:$C$504,"<>")) -> 0 | U6: =IF($A6="","",IF(AND($J6<>"",$K6=""),"DP non reconnu",IF(AND($K6<>"",COUNTIF(Referentiel!$A$81:$A$110,$K6)=0),"DP sans qualification Sécurité valide",IF(AND($N6<>"",$O6=""),"responsable non reconnu",IF(AND($G6<>"",$G6<>"LC"),"créneau rattaché à un autre groupe",IF($I6<>"tenue","",IF(OR($K6="",$O6=""),"couverture incomplète","ok")))))))
A7: =IF($B7="","","S"&TEXT(COUNTIF($B$5:$B7,"<>"),"000")&" — "&TEXT(DAY($B7),"00")&"/"&TEXT(MONTH($B7),"00")&"/"&YEAR($B7)&" ("&$C7&")") -> S003 — 26/09/2026 (samedi) | B7: 46291 | C7: =IF($B7="","",IFERROR(INDEX(Listes!$A$2:$A$8,WEEKDAY($B7,2)),"")) -> samedi | D7: CR-SAM — samedi 10h30-12h00 · B50 [CR-SAM] | E7: =IFERROR(MID($D7,FIND("[",$D7)+1,FIND("]",$D7)-FIND("[",$D7)-1),"") -> CR-SAM | F7: =IFERROR(IF($E7="","",INDEX(Referentiel!$E$54:$E$63,MATCH($E7,Referentiel!$A$54:$A$63,0))&""),"") -> B50 | G7: =IFERROR(IF($E7="","",INDEX(Referentiel!$F$54:$F$63,MATCH($E7,Referentiel!$A$54:$A$63,0))&""),"") -> LC | I7: planifiée | K7: =IF($J7="","",IFERROR(IF(ISNUMBER(FIND("[",$J7)),MID($J7,FIND("[",$J7)+1,FIND("]",$J7)-FIND("[",$J7)-1),IF(ISNUMBER($J7),INDEX(Personnes!$B$5:$B$154,MATCH($J7,Personnes!$A$5:$A$154,0)),IFERROR(INDEX(Personnes!$B$5:$B$154,MATCH($J7&"*",Personnes!$C$5:$C$154,0)),INDEX(Personnes!$B$5:$B$154,MATCH($J7&"*",Personnes!$D$5:$D$154,0))))),"")) | L7: =IFERROR(INDEX(Personnes!$C$5:$C$154,MATCH($K7,Personnes!$B$5:$B$154,0))&"","") | M7: =IFERROR(INDEX(Personnes!$D$5:$D$154,MATCH($K7,Personnes!$B$5:$B$154,0))&"","") | O7: =IF($N7<>"",IF($N7="","",IFERROR(IF(ISNUMBER(FIND("[",$N7)),MID($N7,FIND("[",$N7)+1,FIND("]",$N7)-FIND("[",$N7)-1),IF(ISNUMBER($N7),INDEX(Personnes!$B$5:$B$154,MATCH($N7,Personnes!$A$5:$A$154,0)),IFERROR(INDEX(Personnes!$B$5:$B$154,MATCH($N7&"*",Personnes!$C$5:$C$154,0)),INDEX(Personnes!$B$5:$B$154,MATCH($N7&"*",Personnes!$D$5:$D$154,0))))),"")),IF($E7="","",IFERROR(INDEX(Referentiel!$H$54:$H$63,MATCH($E7,Referentiel!$A$54:$A$63,0)),""))) -> P045 | P7: =IFERROR(INDEX(Personnes!$C$5:$C$154,MATCH($O7,Personnes!$B$5:$B$154,0))&"","") -> SEGUI | Q7: =IFERROR(INDEX(Personnes!$D$5:$D$154,MATCH($O7,Personnes!$B$5:$B$154,0))&"","") -> Danny | T7: =IF($A7="","",COUNTIFS(Presences!$A$5:$A$504,$A7,Presences!$C$5:$C$504,"<>")) -> 0 | U7: =IF($A7="","",IF(AND($J7<>"",$K7=""),"DP non reconnu",IF(AND($K7<>"",COUNTIF(Referentiel!$A$81:$A$110,$K7)=0),"DP sans qualification Sécurité valide",IF(AND($N7<>"",$O7=""),"responsable non reconnu",IF(AND($G7<>"",$G7<>"LC"),"créneau rattaché à un autre groupe",IF($I7<>"tenue","",IF(OR($K7="",$O7=""),"couverture incomplète","ok")))))))
A8: =IF($B8="","","S"&TEXT(COUNTIF($B$5:$B8,"<>"),"000")&" — "&TEXT(DAY($B8),"00")&"/"&TEXT(MONTH($B8),"00")&"/"&YEAR($B8)&" ("&$C8&")") -> S004 — 03/10/2026 (samedi) | B8: 46298 | C8: =IF($B8="","",IFERROR(INDEX(Listes!$A$2:$A$8,WEEKDAY($B8,2)),"")) -> samedi | D8: CR-SAM — samedi 10h30-12h00 · B50 [CR-SAM] | E8: =IFERROR(MID($D8,FIND("[",$D8)+1,FIND("]",$D8)-FIND("[",$D8)-1),"") -> CR-SAM | F8: =IFERROR(IF($E8="","",INDEX(Referentiel!$E$54:$E$63,MATCH($E8,Referentiel!$A$54:$A$63,0))&""),"") -> B50 | G8: =IFERROR(IF($E8="","",INDEX(Referentiel!$F$54:$F$63,MATCH($E8,Referentiel!$A$54:$A$63,0))&""),"") -> LC | I8: planifiée | K8: =IF($J8="","",IFERROR(IF(ISNUMBER(FIND("[",$J8)),MID($J8,FIND("[",$J8)+1,FIND("]",$J8)-FIND("[",$J8)-1),IF(ISNUMBER($J8),INDEX(Personnes!$B$5:$B$154,MATCH($J8,Personnes!$A$5:$A$154,0)),IFERROR(INDEX(Personnes!$B$5:$B$154,MATCH($J8&"*",Personnes!$C$5:$C$154,0)),INDEX(Personnes!$B$5:$B$154,MATCH($J8&"*",Personnes!$D$5:$D$154,0))))),"")) | L8: =IFERROR(INDEX(Personnes!$C$5:$C$154,MATCH($K8,Personnes!$B$5:$B$154,0))&"","") | M8: =IFERROR(INDEX(Personnes!$D$5:$D$154,MATCH($K8,Personnes!$B$5:$B$154,0))&"","") | O8: =IF($N8<>"",IF($N8="","",IFERROR(IF(ISNUMBER(FIND("[",$N8)),MID($N8,FIND("[",$N8)+1,FIND("]",$N8)-FIND("[",$N8)-1),IF(ISNUMBER($N8),INDEX(Personnes!$B$5:$B$154,MATCH($N8,Personnes!$A$5:$A$154,0)),IFERROR(INDEX(Personnes!$B$5:$B$154,MATCH($N8&"*",Personnes!$C$5:$C$154,0)),INDEX(Personnes!$B$5:$B$154,MATCH($N8&"*",Personnes!$D$5:$D$154,0))))),"")),IF($E8="","",IFERROR(INDEX(Referentiel!$H$54:$H$63,MATCH($E8,Referentiel!$A$54:$A$63,0)),""))) -> P045 | P8: =IFERROR(INDEX(Personnes!$C$5:$C$154,MATCH($O8,Personnes!$B$5:$B$154,0))&"","") -> SEGUI | Q8: =IFERROR(INDEX(Personnes!$D$5:$D$154,MATCH($O8,Personnes!$B$5:$B$154,0))&"","") -> Danny | T8: =IF($A8="","",COUNTIFS(Presences!$A$5:$A$504,$A8,Presences!$C$5:$C$504,"<>")) -> 0 | U8: =IF($A8="","",IF(AND($J8<>"",$K8=""),"DP non reconnu",IF(AND($K8<>"",COUNTIF(Referentiel!$A$81:$A$110,$K8)=0),"DP sans qualification Sécurité valide",IF(AND($N8<>"",$O8=""),"responsable non reconnu",IF(AND($G8<>"",$G8<>"LC"),"créneau rattaché à un autre groupe",IF($I8<>"tenue","",IF(OR($K8="",$O8=""),"couverture incomplète","ok")))))))
A9: =IF($B9="","","S"&TEXT(COUNTIF($B$5:$B9,"<>"),"000")&" — "&TEXT(DAY($B9),"00")&"/"&TEXT(MONTH($B9),"00")&"/"&YEAR($B9)&" ("&$C9&")") -> S005 — 10/10/2026 (samedi) | B9: 46305 | C9: =IF($B9="","",IFERROR(INDEX(Listes!$A$2:$A$8,WEEKDAY($B9,2)),"")) -> samedi | D9: CR-SAM — samedi 10h30-12h00 · B50 [CR-SAM] | E9: =IFERROR(MID($D9,FIND("[",$D9)+1,FIND("]",$D9)-FIND("[",$D9)-1),"") -> CR-SAM | F9: =IFERROR(IF($E9="","",INDEX(Referentiel!$E$54:$E$63,MATCH($E9,Referentiel!$A$54:$A$63,0))&""),"") -> B50 | G9: =IFERROR(IF($E9="","",INDEX(Referentiel!$F$54:$F$63,MATCH($E9,Referentiel!$A$54:$A$63,0))&""),"") -> LC | I9: planifiée | K9: =IF($J9="","",IFERROR(IF(ISNUMBER(FIND("[",$J9)),MID($J9,FIND("[",$J9)+1,FIND("]",$J9)-FIND("[",$J9)-1),IF(ISNUMBER($J9),INDEX(Personnes!$B$5:$B$154,MATCH($J9,Personnes!$A$5:$A$154,0)),IFERROR(INDEX(Personnes!$B$5:$B$154,MATCH($J9&"*",Personnes!$C$5:$C$154,0)),INDEX(Personnes!$B$5:$B$154,MATCH($J9&"*",Personnes!$D$5:$D$154,0))))),"")) | L9: =IFERROR(INDEX(Personnes!$C$5:$C$154,MATCH($K9,Personnes!$B$5:$B$154,0))&"","") | M9: =IFERROR(INDEX(Personnes!$D$5:$D$154,MATCH($K9,Personnes!$B$5:$B$154,0))&"","") | O9: =IF($N9<>"",IF($N9="","",IFERROR(IF(ISNUMBER(FIND("[",$N9)),MID($N9,FIND("[",$N9)+1,FIND("]",$N9)-FIND("[",$N9)-1),IF(ISNUMBER($N9),INDEX(Personnes!$B$5:$B$154,MATCH($N9,Personnes!$A$5:$A$154,0)),IFERROR(INDEX(Personnes!$B$5:$B$154,MATCH($N9&"*",Personnes!$C$5:$C$154,0)),INDEX(Personnes!$B$5:$B$154,MATCH($N9&"*",Personnes!$D$5:$D$154,0))))),"")),IF($E9="","",IFERROR(INDEX(Referentiel!$H$54:$H$63,MATCH($E9,Referentiel!$A$54:$A$63,0)),""))) -> P045 | P9: =IFERROR(INDEX(Personnes!$C$5:$C$154,MATCH($O9,Personnes!$B$5:$B$154,0))&"","") -> SEGUI | Q9: =IFERROR(INDEX(Personnes!$D$5:$D$154,MATCH($O9,Personnes!$B$5:$B$154,0))&"","") -> Danny | T9: =IF($A9="","",COUNTIFS(Presences!$A$5:$A$504,$A9,Presences!$C$5:$C$504,"<>")) -> 0 | U9: =IF($A9="","",IF(AND($J9<>"",$K9=""),"DP non reconnu",IF(AND($K9<>"",COUNTIF(Referentiel!$A$81:$A$110,$K9)=0),"DP sans qualification Sécurité valide",IF(AND($N9<>"",$O9=""),"responsable non reconnu",IF(AND($G9<>"",$G9<>"LC"),"créneau rattaché à un autre groupe",IF($I9<>"tenue","",IF(OR($K9="",$O9=""),"couverture incomplète","ok")))))))
A10: =IF($B10="","","S"&TEXT(COUNTIF($B$5:$B10,"<>"),"000")&" — "&TEXT(DAY($B10),"00")&"/"&TEXT(MONTH($B10),"00")&"/"&YEAR($B10)&" ("&$C10&")") -> S006 — 17/10/2026 (samedi) | B10: 46312 | C10: =IF($B10="","",IFERROR(INDEX(Listes!$A$2:$A$8,WEEKDAY($B10,2)),"")) -> samedi | D10: CR-SAM — samedi 10h30-12h00 · B50 [CR-SAM] | E10: =IFERROR(MID($D10,FIND("[",$D10)+1,FIND("]",$D10)-FIND("[",$D10)-1),"") -> CR-SAM | F10: =IFERROR(IF($E10="","",INDEX(Referentiel!$E$54:$E$63,MATCH($E10,Referentiel!$A$54:$A$63,0))&""),"") -> B50 | G10: =IFERROR(IF($E10="","",INDEX(Referentiel!$F$54:$F$63,MATCH($E10,Referentiel!$A$54:$A$63,0))&""),"") -> LC | I10: planifiée | K10: =IF($J10="","",IFERROR(IF(ISNUMBER(FIND("[",$J10)),MID($J10,FIND("[",$J10)+1,FIND("]",$J10)-FIND("[",$J10)-1),IF(ISNUMBER($J10),INDEX(Personnes!$B$5:$B$154,MATCH($J10,Personnes!$A$5:$A$154,0)),IFERROR(INDEX(Personnes!$B$5:$B$154,MATCH($J10&"*",Personnes!$C$5:$C$154,0)),INDEX(Personnes!$B$5:$B$154,MATCH($J10&"*",Personnes!$D$5:$D$154,0))))),"")) | L10: =IFERROR(INDEX(Personnes!$C$5:$C$154,MATCH($K10,Personnes!$B$5:$B$154,0))&"","") | M10: =IFERROR(INDEX(Personnes!$D$5:$D$154,MATCH($K10,Personnes!$B$5:$B$154,0))&"","") | O10: =IF($N10<>"",IF($N10="","",IFERROR(IF(ISNUMBER(FIND("[",$N10)),MID($N10,FIND("[",$N10)+1,FIND("]",$N10)-FIND("[",$N10)-1),IF(ISNUMBER($N10),INDEX(Personnes!$B$5:$B$154,MATCH($N10,Personnes!$A$5:$A$154,0)),IFERROR(INDEX(Personnes!$B$5:$B$154,MATCH($N10&"*",Personnes!$C$5:$C$154,0)),INDEX(Personnes!$B$5:$B$154,MATCH($N10&"*",Personnes!$D$5:$D$154,0))))),"")),IF($E10="","",IFERROR(INDEX(Referentiel!$H$54:$H$63,MATCH($E10,Referentiel!$A$54:$A$63,0)),""))) -> P045 | P10: =IFERROR(INDEX(Personnes!$C$5:$C$154,MATCH($O10,Personnes!$B$5:$B$154,0))&"","") -> SEGUI | Q10: =IFERROR(INDEX(Personnes!$D$5:$D$154,MATCH($O10,Personnes!$B$5:$B$154,0))&"","") -> Danny | T10: =IF($A10="","",COUNTIFS(Presences!$A$5:$A$504,$A10,Presences!$C$5:$C$504,"<>")) -> 0 | U10: =IF($A10="","",IF(AND($J10<>"",$K10=""),"DP non reconnu",IF(AND($K10<>"",COUNTIF(Referentiel!$A$81:$A$110,$K10)=0),"DP sans qualification Sécurité valide",IF(AND($N10<>"",$O10=""),"responsable non reconnu",IF(AND($G10<>"",$G10<>"LC"),"créneau rattaché à un autre groupe",IF($I10<>"tenue","",IF(OR($K10="",$O10=""),"couverture incomplète","ok")))))))
A11: =IF($B11="","","S"&TEXT(COUNTIF($B$5:$B11,"<>"),"000")&" — "&TEXT(DAY($B11),"00")&"/"&TEXT(MONTH($B11),"00")&"/"&YEAR($B11)&" ("&$C11&")") -> S007 — 24/10/2026 (samedi) | B11: 46319 | C11: =IF($B11="","",IFERROR(INDEX(Listes!$A$2:$A$8,WEEKDAY($B11,2)),"")) -> samedi | D11: CR-SAM — samedi 10h30-12h00 · B50 [CR-SAM] | E11: =IFERROR(MID($D11,FIND("[",$D11)+1,FIND("]",$D11)-FIND("[",$D11)-1),"") -> CR-SAM | F11: =IFERROR(IF($E11="","",INDEX(Referentiel!$E$54:$E$63,MATCH($E11,Referentiel!$A$54:$A$63,0))&""),"") -> B50 | G11: =IFERROR(IF($E11="","",INDEX(Referentiel!$F$54:$F$63,MATCH($E11,Referentiel!$A$54:$A$63,0))&""),"") -> LC | I11: planifiée | K11: =IF($J11="","",IFERROR(IF(ISNUMBER(FIND("[",$J11)),MID($J11,FIND("[",$J11)+1,FIND("]",$J11)-FIND("[",$J11)-1),IF(ISNUMBER($J11),INDEX(Personnes!$B$5:$B$154,MATCH($J11,Personnes!$A$5:$A$154,0)),IFERROR(INDEX(Personnes!$B$5:$B$154,MATCH($J11&"*",Personnes!$C$5:$C$154,0)),INDEX(Personnes!$B$5:$B$154,MATCH($J11&"*",Personnes!$D$5:$D$154,0))))),"")) | L11: =IFERROR(INDEX(Personnes!$C$5:$C$154,MATCH($K11,Personnes!$B$5:$B$154,0))&"","") | M11: =IFERROR(INDEX(Personnes!$D$5:$D$154,MATCH($K11,Personnes!$B$5:$B$154,0))&"","") | O11: =IF($N11<>"",IF($N11="","",IFERROR(IF(ISNUMBER(FIND("[",$N11)),MID($N11,FIND("[",$N11)+1,FIND("]",$N11)-FIND("[",$N11)-1),IF(ISNUMBER($N11),INDEX(Personnes!$B$5:$B$154,MATCH($N11,Personnes!$A$5:$A$154,0)),IFERROR(INDEX(Personnes!$B$5:$B$154,MATCH($N11&"*",Personnes!$C$5:$C$154,0)),INDEX(Personnes!$B$5:$B$154,MATCH($N11&"*",Personnes!$D$5:$D$154,0))))),"")),IF($E11="","",IFERROR(INDEX(Referentiel!$H$54:$H$63,MATCH($E11,Referentiel!$A$54:$A$63,0)),""))) -> P045 | P11: =IFERROR(INDEX(Personnes!$C$5:$C$154,MATCH($O11,Personnes!$B$5:$B$154,0))&"","") -> SEGUI | Q11: =IFERROR(INDEX(Personnes!$D$5:$D$154,MATCH($O11,Personnes!$B$5:$B$154,0))&"","") -> Danny | T11: =IF($A11="","",COUNTIFS(Presences!$A$5:$A$504,$A11,Presences!$C$5:$C$504,"<>")) -> 0 | U11: =IF($A11="","",IF(AND($J11<>"",$K11=""),"DP non reconnu",IF(AND($K11<>"",COUNTIF(Referentiel!$A$81:$A$110,$K11)=0),"DP sans qualification Sécurité valide",IF(AND($N11<>"",$O11=""),"responsable non reconnu",IF(AND($G11<>"",$G11<>"LC"),"créneau rattaché à un autre groupe",IF($I11<>"tenue","",IF(OR($K11="",$O11=""),"couverture incomplète","ok")))))))
