Workbook

Sheet Lisez-moi
A1: Classeur de paramétrage — Apnée Attitude — saison 2026-2027
B4: À quoi sert ce classeur
B5: Ce classeur porte le paramétrage du suivi des entraînements pour tout le club : référentiels, cadre d'organisation, personnes, calendrier perpétuel. Il ne contient aucune donnée de suivi — celles-ci vivent dans un classeur par ligne d'eau.
B6: Il sert aussi de contrat de données à la future application : un onglet correspond à une table, une colonne à un champ, une ligne à un enregistrement. Sa structure ne doit donc pas être modifiée.
B8: Trois couleurs de fond, trois natures de cellule
B9: Blanc — vous saisissez librement.
B10: Vert clair — vous saisissez avec une aide : liste déroulante, ou sélection d'une personne.
B11: Gris — valeur calculée. N'y touchez pas, elle se met à jour seule.
B12: C'est le seul code couleur du classeur. Aucune information métier n'est portée par une couleur : si une information manque quelque part, il faut lui ajouter une colonne.
B14: Des tables Excel, pas des plages figées
B15: Chaque table de données est une Table Excel nommée, avec une seule ligne libre en réserve. Tapez dans cette ligne : la table s'agrandit d'elle-même et reprend formules, formats et listes déroulantes de la ligne du dessus. Inutile d'insérer une ligne ou de recopier quoi que ce soit.
B17: Une personne, plusieurs rôles
B18: Dans Inscriptions, une ligne porte un seul rôle pour un seul groupe. Une personne encadrante en L3 et élève en L4 a donc **deux lignes** : une (L3, encadrant) et une (L4, élève). Le contrôle de doublon porte sur le quadruplet saison, personne, groupe, rôle — deux lignes de rôles différents ne sont donc pas des doublons.
... B45: Version 1.3 — 21 août 2026. Généré depuis les documents de cadrage 1.2 à 1.6 (dossier site_apnee/Cadrage_v2).

Sheet Referentiels
A1: Référentiels généraux
A2: Huit petits référentiels, regroupés ici plutôt que dispersés sur autant d'onglets presque vides. Chaque section est une Table Excel à part entière.
A4: Sommaire
A5: =HYPERLINK("#Referentiels!A17","Disciplines")
A6: =HYPERLINK("#Referentiels!A26","Groupes de niveaux")
A7: =HYPERLINK("#Referentiels!A41","Familles d'objectifs")
A8: =HYPERLINK("#Referentiels!A53","Familles de compétences")
A9: =HYPERLINK("#Referentiels!A66","Qualifications")
A10: =HYPERLINK("#Referentiels!A81","Bassins")
A11: =HYPERLINK("#Referentiels!A88","Régimes d'ouverture")
A12: =HYPERLINK("#Referentiels!A98","Périodes d'application des régimes")
A14: Disciplines
A15: Liste paramétrable. Le code est l'identifiant : ne jamais le modifier.
A16: Code | B16: Libellé | C16: Ordre | D16: Dans le MVP | E16: Commentaire
A17: DYN | B17: Apnée dynamique avec palmes | C17: 1 | D17: oui | E17: Seule discipline retenue au MVP (décision D-23).
A18: DNF | B18: Apnée dynamique sans palme | C18: 2 | D18: non | E18: Hors MVP. Aucun plan d'entraînement dédié à ce jour.
A19: STA | B19: Apnée statique | C19: 3 | D19: non | E19: Hors MVP. Aucun plan d'entraînement dédié à ce jour.
A20: PRO | B20: Apnée en profondeur | C20: 4 | D20: non | E20: Hors MVP. Organisation en fosse et milieu naturel, à cadrer.
A23: Groupes de niveaux
A24: Paramétrables par discipline. « Groupe précédent » rend la progression explicite d'un niveau au suivant.
A25: Code | B25: Libellé | C25: Discipline | D25: Rang | E25: Groupe précédent | F25: Dans le MVP | G25: Commentaire
A26: L1 | B26: L1 — Initiation | C26: DYN | D26: 1 | F26: oui | G26: Débutants
A27: L2 | B27: L2 — Intermédiaire | C27: DYN | D27: 2 | E27: L1 | F27: oui | G27: Intermédiaires
A28: L3 | B28: L3 — Confirmé | C28: DYN | D28: 3 | E28: L2 | F28: oui | G28: Confirmés
A29: L4 | B29: L4 — Expert | C29: DYN | D29: 4 | E29: L3 | F29: oui | G29: Experts
A30: LC | B30: LC — Compétition | C30: DYN | D30: 5 | E30: L4 | F30: oui | G30: Pas de plan propre : séances calquées sur le L4, logique de records.
A31: DNF1 | B31: DNF 1 | C31: DNF | D31: 1 | F31: non | G31: Hors MVP
A32: DNF2 | B32: DNF 2 | C32: DNF | D32: 2 | E32: DNF1 | F32: non | G32: Hors MVP
A33: STA1 | B33: STA 1 | C33: STA | D33: 1 | F33: non | G33: Hors MVP
A34: STA2 | B34: STA 2 | C34: STA | D34: 2 | E34: STA1 | F34: non | G34: Hors MVP
A35: STAC | B35: STA compétition | C35: STA | D35: 3 | E35: STA2 | F35: non | G35: Hors MVP
A38: Familles d'objectifs
A39: Sept familles couvrent les objectifs des quatre niveaux. Chaque groupe prélève deux seuils sur l'échelle d'une famille.
A40: Code | B40: Libellé | C40: Discipline | D40: Unité | E40: Ce qui varie d'un niveau à l'autre | F40: Commentaire
A41: DIST | B41: Distance maximale | C41: DYN | D41: mètre | E41: la distance | F41: Objectif structurant de chaque niveau.
A42: SERIE_HC | B42: Série hypercapnique | C42: DYN | D42: temps de départ | E42: l'intervalle de départ, à 4 × 50 m constants
A43: SERIE_CT | B43: Série courte à récupération brève | C43: DYN | D43: nombre × distance + secondes | E43: le nombre de répétitions et la récupération | F43: Absente au-delà du L2.
A44: STA_DYN | B44: Enchaînement statique-dynamique | C44: DYN | D44: temps + mètre | E44: la durée de statique et la distance | F44: Exercice de la dynamique, pas une discipline distincte.
A45: LENT | B45: Nage lente à durée imposée | C45: DYN | D45: temps | E45: la durée imposée pour 50 m
A46: BRASSE | B46: Brasse (sans palme) | C46: DYN | D46: mètre | E46: la distance | F46: Exercice de la dynamique, pas une discipline distincte.
...

Sheet Objectifs_Niveaux
A1: Objectifs par niveau
A2: Intitulés reproduits littéralement des plans d'entraînement. Le critère est porté par l'objectif, jamais par le logiciel.
A4: ID | B4: Groupe | C4: Famille | D4: Type | E4: Intitulé | F4: Distance (m) | G4: Durée STA | H4: Temps cible | I4: Intervalle départ | J4: Récupération | K4: Nb séries | L4: Nb répétitions exigé | M4: Intervalle max entre départs | N4: Contrainte requise | O4: Critère de validation (texte littéral) | P4: Source
A5: L1-M1 | B5: L1 | C5: DIST | D5: maîtrise | E5: 50m dyn bi-palmes | F5: 50 | L5: 7 | M5: 7' | N5: hypercapnique et/ou hypoxique | O5: Pouvoir réaliser la distance 7 fois dans la même séance avec contraintes hypercapniques et/ou hypoxiques. | P5: AA - Plan d'entrainement débutants (L1) V.2.2024, p. 3
A6: L1-M2 | B6: L1 | C6: SERIE_HC | D6: maîtrise | E6: 4 x 50m départ 2' | F6: 50 | I6: 2' | K6: 4 | L6: 7 | M6: 7' | N6: hypercapnique et/ou hypoxique | O6: Pouvoir réaliser la distance 7 fois dans la même séance avec contraintes hypercapniques et/ou hypoxiques. | P6: AA - Plan d'entrainement débutants (L1) V.2.2024, p. 3
A7: L1-M3 | B7: L1 | C7: SERIE_CT | D7: maîtrise | E7: 4 x 25m récup 15'' | F7: 25 | J7: 15'' | K7: 4 | L7: 7 | M7: 7' | N7: hypercapnique et/ou hypoxique | O7: Pouvoir réaliser la distance 7 fois dans la même séance avec contraintes hypercapniques et/ou hypoxiques. | P7: AA - Plan d'entrainement débutants (L1) V.2.2024, p. 3
A8: L1-M4 | B8: L1 | C8: STA_DYN | D8: maîtrise | E8: 30'' de STA + 50m | F8: 50 | G8: 30'' | L8: 7 | M8: 7' | N8: hypercapnique et/ou hypoxique | O8: Pouvoir réaliser la distance 7 fois dans la même séance avec contraintes hypercapniques et/ou hypoxiques. | P8: AA - Plan d'entrainement débutants (L1) V.2.2024, p. 3
A9: L1-M5 | B9: L1 | C9: LENT | D9: maîtrise | E9: 50m lent (1'15'') | F9: 50 | H9: 1'15'' | L9: 7 | M9: 7' | N9: hypercapnique et/ou hypoxique | O9: Pouvoir réaliser la distance 7 fois dans la même séance avec contraintes hypercapniques et/ou hypoxiques. | P9: AA - Plan d'entrainement débutants (L1) V.2.2024, p. 3
A10: L1-M6 | B10: L1 | C10: BRASSE | D10: maîtrise | E10: 37,5m en brasse | F10: 37.5 | L10: 7 | M10: 7' | N10: hypercapnique et/ou hypoxique | O10: Pouvoir réaliser la distance 7 fois dans la même séance avec contraintes hypercapniques et/ou hypoxiques. | P10: AA - Plan d'entrainement débutants (L1) V.2.2024, p. 3
A11: L1-A1 | B11: L1 | C11: DIST | D11: acquisition | E11: 65m dyn bi-palmes | F11: 65 | L11: 1 | N11: meilleures conditions | O11: Pouvoir réaliser la distance ou l'exercice une fois en étant mis dans les meilleures conditions. | P11: AA - Plan d'entrainement débutants (L1) V.2.2024, p. 3
A12: L1-A2 | B12: L1 | C12: SERIE_HC | D12: acquisition | E12: 4 x 50m départ 1'45'' | F12: 50 | I12: 1'45'' | K12: 4 | L12: 1 | N12: meilleures conditions | O12: Pouvoir réaliser la distance ou l'exercice une fois en étant mis dans les meilleures conditions. | P12: AA - Plan d'entrainement débutants (L1) V.2.2024, p. 3
A13: L1-A3 | B13: L1 | C13: SERIE_CT | D13: acquisition | E13: 8 x 25m récup 15'' | F13: 25 | J13: 15'' | K13: 8 | L13: 1 | N13: meilleures conditions | O13: Pouvoir réaliser la distance ou l'exercice une fois en étant mis dans les meilleures conditions. | P13: AA - Plan d'entrainement débutants (L1) V.2.2024, p. 3
A14: L1-A4 | B14: L1 | C14: STA_DYN | D14: acquisition | E14: 1' de STA + 50m | F14: 50 | G14: 1' | L14: 1 | N14: meilleures conditions | O14: Pouvoir réaliser la distance ou l'exercice une fois en étant mis dans les meilleures conditions. | P14: AA - Plan d'entrainement débutants (L1) V.2.2024, p. 3
A15: L1-A5 | B15: L1 | C15: LENT | D15: acquisition | E15: 50m lent (1'30'') | F15: 50 | H15: 1'30'' | L15: 1 | N15: meilleures conditions | O15: Pouvoir réaliser la distance ou l'exercice une fois en étant mis dans les meilleures conditions. | P15: AA - Plan d'entrainement débutants (L1) V.2.2024, p. 3
A16: L1-A6 | B16: L1 | C16: BRASSE | D16: acquisition | E16: 50m en brasse | F16: 50 | L16: 1 | N16: meilleures conditions | O16: Pouvoir réaliser la distance ou l'exercice une fois en étant mis dans les meilleures conditions. | P16: AA - Plan d'entrainement débutants (L1) V.2.2024, p. 3
A17: L2-M1 | B17: L2 | C17: DIST | D17: maîtrise | E17: 75m dyn bi-palmes | F17: 75 | L17: 5 | M17: 7' | N17: hypercapnique et/ou hypoxique | O17: Pouvoir réaliser la distance 5 fois dans la même séance avec contraintes hypercapniques et/ou hypoxiques. | P17: AA - Plan d'entrainement intermédiaires (L2) V.2.2024, p. 3
A18: L2-M2 | B18: L2 | C18: SERIE_HC | D18: maîtrise | E18: 4 x 50m départ 1'30'' | F18: 50 | I18: 1'30'' | K18: 4 | L18: 5 | M18: 7' | N18: hypercapnique et/ou hypoxique | O18: Pouvoir réaliser la distance 5 fois dans la même séance avec contraintes hypercapniques et/ou hypoxiques. | P18: AA - Plan d'entrainement intermédiaires (L2) V.2.2024, p. 3
A19: L2-M3 | B19: L2 | C19: SERIE_CT | D19: maîtrise | E19: 4 x 25m récup 10'' | F19: 25 | J19: 10'' | K19: 4 | L19: 5 | M19: 7' | N19: hypercapnique et/ou hypoxique | O19: Pouvoir réaliser la distance 5 fois dans la même séance avec contraintes hypercapniques et/ou hypoxiques. | P19: AA - Plan d'entrainement intermédiaires (L2) V.2.2024, p. 3
A20: L2-M4 | B20: L2 | C20: STA_DYN | D20: maîtrise | E20: 1' de STA + 50m | F20: 50 | G20: 1' | L20: 5 | M20: 7' | N20: hypercapnique et/ou hypoxique | O20: Pouvoir réaliser la distance 5 fois dans la même séance avec contraintes hypercapniques et/ou hypoxiques. | P20: AA - Plan d'entrainement intermédiaires (L2) V.2.2024, p. 3
A21: L2-M5 | B21: L2 | C21: LENT | D21: maîtrise | E21: 50m lent (1'30'') | F21: 50 | H21: 1'30'' | L21: 5 | M21: 7' | N21: hypercapnique et/ou hypoxique | O21: Pouvoir réaliser la distance 5 fois dans la même séance avec contraintes hypercapniques et/ou hypoxiques. | P21: AA - Plan d'entrainement intermédiaires (L2) V.2.2024, p. 3
A22: L2-M6 | B22: L2 | C22: BRASSE | D22: maîtrise | E22: 50m en brasse | F22: 50 | L22: 5 | M22: 7' | N22: hypercapnique et/ou hypoxique | O22: Pouvoir réaliser la distance 5 fois dans la même séance avec contraintes hypercapniques et/ou hypoxiques. | P22: AA - Plan d'entrainement intermédiaires (L2) V.2.2024, p. 3
A23: L2-M7 | B23: L2 | C23: VOL_PUL | D23: maîtrise | E23: 50m FRC | F23: 50 | L23: 5 | M23: 7' | N23: hypercapnique et/ou hypoxique | O23: Pouvoir réaliser la distance 5 fois dans la même séance avec contraintes hypercapniques et/ou hypoxiques. | P23: AA - Plan d'entrainement intermédiaires (L2) V.2.2024, p. 3
A24: L2-A1 | B24: L2 | C24: DIST | D24: acquisition | E24: 85m dyn bi-palmes | F24: 85 | L24: 1 | N24: meilleures conditions | O24: Pouvoir réaliser la distance ou l'exercice une fois en étant mis dans les meilleures conditions. | P24: AA - Plan d'entrainement intermédiaires (L2) V.2.2024, p. 3
A25: L2-A2 | B25: L2 | C25: SERIE_HC | D25: acquisition | E25: 4 x 50m départ 1'20'' | F25: 50 | I25: 1'20'' | K25: 4 | L25: 1 | N25: meilleures conditions | O25: Pouvoir réaliser la distance ou l'exercice une fois en étant mis dans les meilleures conditions. | P25: AA - Plan d'entrainement intermédiaires (L2) V.2.2024, p. 3
A26: L2-A3 | B26: L2 | C26: SERIE_CT | D26: acquisition | E26: 8 x 25m récup 10'' | F26: 25 | J26: 10'' | K26: 8 | L26: 1 | N26: meilleures conditions | O26: Pouvoir réaliser la distance ou l'exercice une fois en étant mis dans les meilleures conditions. | P26: AA - Plan d'entrainement intermédiaires (L2) V.2.2024, p. 3
A27: L2-A4 | B27: L2 | C27: STA_DYN | D27: acquisition | E27: 30'' de STA + 75m | F27: 75 | G27: 30'' | L27: 1 | N27: meilleures conditions | O27: Pouvoir réaliser la distance ou l'exercice une fois en étant mis dans les meilleures conditions. | P27: AA - Plan d'entrainement intermédiaires (L2) V.2.2024, p. 3
A28: L2-A5 | B28: L2 | C28: LENT | D28: acquisition | E28: 50m lent (1'45'') | F28: 50 | H28: 1'45'' | L28: 1 | N28: meilleures conditions | O28: Pouvoir réaliser la distance ou l'exercice une fois en étant mis dans les meilleures conditions. | P28: AA - Plan d'entrainement intermédiaires (L2) V.2.2024, p. 3
A29: L2-A6 | B29: L2 | C29: BRASSE | D29: acquisition | E29: 65m en brasse | F29: 65 | L29: 1 | N29: meilleures conditions | O29: Pouvoir réaliser la distance ou l'exercice une fois en étant mis dans les meilleures conditions. | P29: AA - Plan d'entrainement intermédiaires (L2) V.2.2024, p. 3
A30: L2-A7 | B30: L2 | C30: VOL_PUL | D30: acquisition | E30: 50m PV | F30: 50 | L30: 1 | N30: meilleures conditions | O30: Pouvoir réaliser la distance ou l'exercice une fois en étant mis dans les meilleures conditions. | P30: AA - Plan d'entrainement intermédiaires (L2) V.2.2024, p. 3
A31: L3-M1 | B31: L3 | C31: DIST | D31: maîtrise | E31: 100m dyn | F31: 100 | L31: 3 | M31: 7' | N31: hypercapnique et/ou hypoxique | O31: Pouvoir réaliser la distance 3 fois dans la même séance avec contraintes hypercapniques et/ou hypoxiques. | P31: AA - Plan d'entrainement confirmés (L3) V.2.2024, p. 3
A32: L3-M2 | B32: L3 | C32: SERIE_HC | D32: maîtrise | E32: 4 x 50m départ 1'10'' | F32: 50 | I32: 1'10'' | K32: 4 | L32: 3 | M32: 7' | N32: hypercapnique et/ou hypoxique | O32: Pouvoir réaliser la distance 3 fois dans la même séance avec contraintes hypercapniques et/ou hypoxiques. | P32: AA - Plan d'entrainement confirmés (L3) V.2.2024, p. 3
A33: L3-M3 | B33: L3 | C33: STA_DYN | D33: maîtrise | E33: 1' de STA + 75m | F33: 75 | G33: 1' | L33: 3 | M33: 7' | N33: hypercapnique et/ou hypoxique | O33: Pouvoir réaliser la distance 3 fois dans la même séance avec contraintes hypercapniques et/ou hypoxiques. | P33: AA - Plan d'entrainement confirmés (L3) V.2.2024, p. 3
A34: L3-M4 | B34: L3 | C34: LENT | D34: maîtrise | E34: 50m lent (2') | F34: 50 | H34: 2' | L34: 3 | M34: 7' | N34: hypercapnique et/ou hypoxique | O34: Pouvoir réaliser la distance 3 fois dans la même séance avec contraintes hypercapniques et/ou hypoxiques. | P34: AA - Plan d'entrainement confirmés (L3) V.2.2024, p. 3
A35: L3-M5 | B35: L3 | C35: BRASSE | D35: maîtrise | E35: 65m en brasse | F35: 65 | L35: 3 | M35: 7' | N35: hypercapnique et/ou hypoxique | O35: Pouvoir réaliser la distance 3 fois dans la même séance avec contraintes hypercapniques et/ou hypoxiques. | P35: AA - Plan d'entrainement confirmés (L3) V.2.2024, p. 3
A36: L3-A1 | B36: L3 | C36: DIST | D36: acquisition | E36: 125m dyn | F36: 125 | L36: 1 | N36: meilleures conditions | O36: Pouvoir réaliser la distance ou l'exercice une fois en étant mis dans les meilleures conditions. | P36: AA - Plan d'entrainement confirmés (L3) V.2.2024, p. 3
A37: L3-A2 | B37: L3 | C37: SERIE_HC | D37: acquisition | E37: 4 x 50m départ 1' | F37: 50 | I37: 1' | K37: 4 | L37: 1 | N37: meilleures conditions | O37: Pouvoir réaliser la distance ou l'exercice une fois en étant mis dans les meilleures conditions. | P37: AA - Plan d'entrainement confirmés (L3) V.2.2024, p. 3
A38: L3-A3 | B38: L3 | C38: STA_DYN | D38: acquisition | E38: 1'30'' de STA + 75m | F38: 75 | G38: 1'30'' | L38: 1 | N38: meilleures conditions | O38: Pouvoir réaliser la distance ou l'exercice une fois en étant mis dans les meilleures conditions. | P38: AA - Plan d'entrainement confirmés (L3) V.2.2024, p. 3
A39: L3-A4 | B39: L3 | C39: LENT | D39: acquisition | E39: 50m lent (2'30'') | F39: 50 | H39: 2'30'' | L39: 1 | N39: meilleures conditions | O39: Pouvoir réaliser la distance ou l'exercice une fois en étant mis dans les meilleures conditions. | P39: AA - Plan d'entrainement confirmés (L3) V.2.2024, p. 3
A40: L3-A5 | B40: L3 | C40: BRASSE | D40: acquisition | E40: 75m en brasse | F40: 75 | L40: 1 | N40: meilleures conditions | O40: Pouvoir réaliser la distance ou l'exercice une fois en étant mis dans les meilleures conditions. | P40: AA - Plan d'entrainement confirmés (L3) V.2.2024, p. 3
A41: L4-M1 | B41: L4 | C41: DIST | D41: maîtrise | E41: 125m dyn | F41: 125 | N41: aucune contrainte particulière | O41: Pouvoir réaliser la distance sans contrainte particulière, régulièrement, sans incident. — critère qualitatif, non calculable. | P41: AA - Plan d'entrainement experts (L4) V.1.2025, p. 3
...

Sheet Competences_Niveaux
A1: Niveau attendu par compétence et par groupe
A2: Une seule table pour toutes les lignes : c'est ce qui garantit la cohérence d'ensemble de la progression.
A4: Compétence | B4: Libellé | C4: Groupe | D4: Niveau attendu | E4: Commentaire
A5: LEST | B5: Lestage | C5: L1 | D5: en cours
A6: LEST | B6: Lestage | C6: L2 | D6: acquis
A7: LEST | B7: Lestage | C7: L3 | D7: acquis
A8: LEST | B8: Lestage | C8: L4 | D8: expert
A9: LEST | B9: Lestage | C9: LC | D9: expert
A10: HYDRO | B10: Hydrodynamisme | C10: L1 | D10: en cours
A11: HYDRO | B11: Hydrodynamisme | C11: L2 | D11: acquis
A12: HYDRO | B12: Hydrodynamisme | C12: L3 | D12: acquis
A13: HYDRO | B13: Hydrodynamisme | C13: L4 | D13: expert
A14: HYDRO | B14: Hydrodynamisme | C14: LC | D14: expert
A15: PALM_BI | B15: Palmage bi-palmes | C15: L1 | D15: en cours
A16: PALM_BI | B16: Palmage bi-palmes | C16: L2 | D16: acquis
... A44: BRASSE | B44: Brasse DNF | C44: LC | D44: expert

Sheet Creneaux
A1: Créneaux de piscine
A2: La structure hebdomadaire récurrente. Les groupes de niveaux accueillis sont dans l'onglet Creneaux_Groupes, avec leur date d'effet.
A4: ID | B4: Jour | C4: Heure début | D4: Heure fin | E4: Bassin | F4: Nb de lignes ouvertes | G4: Régime | H4: Actif | I4: Libellé (calculé) | J4: Commentaire
A5: CR-LUN | B5: lundi | C5: 21h30 | D5: 22h30 | E5: B50 | F5: 1 | G5: NOMINAL | H5: oui | I5: =IF($A5="","",$A5&" — "&$B5&IF($C5=""," (horaire à saisir)"," "&$C5&"-"&$D5)&IF($E5=""," "," · "&$E5)&" ["&$A5&"]") | J5: Jour confirmé par le planning 2026-27. Horaires et groupe à saisir.
A6: CR-MAR | B6: mardi | C6: 21h30 | D6: 22h30 | E6: B50 | F6: 1 | G6: NOMINAL | H6: oui | I6: =IF($A6="","",$A6&" — "&$B6&IF($C6=""," (horaire à saisir)"," "&$C6&"-"&$D6)&IF($E6=""," "," · "&$E6)&" ["&$A6&"]") | J6: Jour confirmé par le planning 2026-27. Horaires et groupe à saisir.
A7: CR-MER | B7: mercredi | C7: 21h30 | D7: 22h30 | E7: B50 | F7: 1 | G7: NOMINAL | H7: oui | I7: =IF($A7="","",$A7&" — "&$B7&IF($C7=""," (horaire à saisir)"," "&$C7&"-"&$D7)&IF($E7=""," "," · "&$E7)&" ["&$A7&"]") | J7: Jour confirmé par le planning 2026-27. Horaires et groupe à saisir.
A8: CR-VEN | B8: vendredi | C8: 21h30 | D8: 22h30 | E8: B50 | F8: 1 | G8: NOMINAL | H8: oui | I8: =IF($A8="","",$A8&" — "&$B8&IF($C8=""," (horaire à saisir)"," "&$C8&"-"&$D8)&IF($E8=""," "," · "&$E8)&" ["&$A8&"]") | J8: Jour confirmé par le planning 2026-27. Horaires et groupe à saisir.
A9: CR-SAM | B9: samedi | C9: 10h30 | D9: 12h00 | E9: B50 | F9: 1 | G9: NOMINAL | H9: oui | I9: =IF($A9="","",$A9&" — "&$B9&IF($C9=""," (horaire à saisir)"," "&$C9&"-"&$D9)&IF($E9=""," "," · "&$E9)&" ["&$A9&"]") | J9: Jour confirmé par le planning 2026-27. Horaires et groupe à saisir.
A10: CR-DIM | B10: dimanche | E10: B50 | F10: 1 | G10: NOMINAL | H10: non | I10: =IF($A10="","",$A10&" — "&$B10&IF($C10=""," (horaire à saisir)"," "&$C10&"-"&$D10)&IF($E10=""," "," · "&$E10)&" ["&$A10&"]") | J10: Colonne présente dans le planning mais sans directeur de bassin.
I11: =IF($A11="","",$A11&" — "&$B11&IF($C11=""," (horaire à saisir)"," "&$C11&"-"&$D11)&IF($E11=""," "," · "&$E11)&" ["&$A11&"]")

Sheet Creneaux_Groupes
A1: Groupes de niveaux et encadrants, par créneau
A2: Le calendrier perpétuel. Un créneau peut accueillir plusieurs groupes, et un couple créneau / groupe plusieurs encadrants : une ligne par encadrant. La répartition fine se règle ensuite séance par séance dans le classeur de ligne.
A4: Créneau | B4: Créneau (ID) | C4: Date d'effet | D4: Groupe de niveau | E4: Sélection par nom ou prénom | F4: Encadrant (ID) | G4: Nom | H4: Prénom | I4: Nb de lignes allouées | J4: Commentaire | K4: Contrôle
A5: CR-LUN — lundi 21h30-22h30 · B50 [CR-LUN] | B5: =IFERROR(MID($A5,FIND("[",$A5)+1,FIND("]",$A5)-FIND("[",$A5)-1),"") | C5: 46266 | D5: L2 | E5: Sophie [P028] | F5: =IFERROR(MID($E5,FIND("[",$E5)+1,FIND("]",$E5)-FIND("[",$E5)-1),"") | G5: =IFERROR(INDEX(Personnes!$B$5:$B$153,MATCH($F5,Personnes!$A$5:$A$153,0))&"","") | H5: =IFERROR(INDEX(Personnes!$C$5:$C$153,MATCH($F5,Personnes!$A$5:$A$153,0))&"","") | I5: 1 | K5: =IF($A5="","",IF($B5="","créneau non reconnu",IF($C5="","date d’effet manquante",IF($D5="","groupe manquant",IF(COUNTIFS($B$5:$B$80,$B5,$C$5:$C$80,$C5,$D$5:$D$80,$D5,$F$5:$F$80,$F5)>1,"doublon créneau/date/groupe/encadrant",IF($F5="","encadrant à désigner","ok"))))))
A6: CR-LUN — lundi 21h30-22h30 · B50 [CR-LUN] | B6: =IFERROR(MID($A6,FIND("[",$A6)+1,FIND("]",$A6)-FIND("[",$A6)-1),"") | C6: 46266 | D6: L2 | E6: Charline [P007] | F6: =IFERROR(MID($E6,FIND("[",$E6)+1,FIND("]",$E6)-FIND("[",$E6)-1),"") | G6: =IFERROR(INDEX(Personnes!$B$5:$B$153,MATCH($F6,Personnes!$A$5:$A$153,0))&"","") | H6: =IFERROR(INDEX(Personnes!$C$5:$C$153,MATCH($F6,Personnes!$A$5:$A$153,0))&"","") | I6: 1 | K6: =IF($A6="","",IF($B6="","créneau non reconnu",IF($C6="","date d’effet manquante",IF($D6="","groupe manquant",IF(COUNTIFS($B$5:$B$80,$B6,$C$5:$C$80,$C6,$D$5:$D$80,$D6,$F$5:$F$80,$F6)>1,"doublon créneau/date/groupe/encadrant",IF($F6="","encadrant à désigner","ok"))))))
A7: CR-LUN — lundi 21h30-22h30 · B50 [CR-LUN] | B7: =IFERROR(MID($A7,FIND("[",$A7)+1,FIND("]",$A7)-FIND("[",$A7)-1),"") | C7: 46266 | D7: L3 | E7: Gabrielle [P035] | F7: =IFERROR(MID($E7,FIND("[",$E7)+1,FIND("]",$E7)-FIND("[",$E7)-1),"") | G7: =IFERROR(INDEX(Personnes!$B$5:$B$153,MATCH($F7,Personnes!$A$5:$A$153,0))&"","") | H7: =IFERROR(INDEX(Personnes!$C$5:$C$153,MATCH($F7,Personnes!$A$5:$A$153,0))&"","") | I7: 1 | K7: =IF($A7="","",IF($B7="","créneau non reconnu",IF($C7="","date d’effet manquante",IF($D7="","groupe manquant",IF(COUNTIFS($B$5:$B$80,$B7,$C$5:$C$80,$C7,$D$5:$D$80,$D7,$F$5:$F$80,$F7)>1,"doublon créneau/date/groupe/encadrant",IF($F7="","encadrant à désigner","ok"))))))
A8: CR-LUN — lundi 21h30-22h30 · B50 [CR-LUN] | B8: =IFERROR(MID($A8,FIND("[",$A8)+1,FIND("]",$A8)-FIND("[",$A8)-1),"") | C8: 46266 | D8: L3 | E8: Etienne CDV [P011] | F8: =IFERROR(MID($E8,FIND("[",$E8)+1,FIND("]",$E8)-FIND("[",$E8)-1),"") | G8: =IFERROR(INDEX(Personnes!$B$5:$B$153,MATCH($F8,Personnes!$A$5:$A$153,0))&"","") | H8: =IFERROR(INDEX(Personnes!$C$5:$C$153,MATCH($F8,Personnes!$A$5:$A$153,0))&"","") | I8: 1 | K8: =IF($A8="","",IF($B8="","créneau non reconnu",IF($C8="","date d’effet manquante",IF($D8="","groupe manquant",IF(COUNTIFS($B$5:$B$80,$B8,$C$5:$C$80,$C8,$D$5:$D$80,$D8,$F$5:$F$80,$F8)>1,"doublon créneau/date/groupe/encadrant",IF($F8="","encadrant à désigner","ok"))))))
A9: CR-MAR — mardi 21h30-22h30 · B50 [CR-MAR] | B9: =IFERROR(MID($A9,FIND("[",$A9)+1,FIND("]",$A9)-FIND("[",$A9)-1),"") | C9: 46266 | D9: L1 | E9: Dominique BEAUVALLET [P030] | F9: =IFERROR(MID($E9,FIND("[",$E9)+1,FIND("]",$E9)-FIND("[",$E9)-1),"") | G9: =IFERROR(INDEX(Personnes!$B$5:$B$153,MATCH($F9,Personnes!$A$5:$A$153,0))&"","") | H9: =IFERROR(INDEX(Personnes!$C$5:$C$153,MATCH($F9,Personnes!$A$5:$A$153,0))&"","") | I9: 1 | K9: =IF($A9="","",IF($B9="","créneau non reconnu",IF($C9="","date d’effet manquante",IF($D9="","groupe manquant",IF(COUNTIFS($B$5:$B$80,$B9,$C$5:$C$80,$C9,$D$5:$D$80,$D9,$F$5:$F$80,$F9)>1,"doublon créneau/date/groupe/encadrant",IF($F9="","encadrant à désigner","ok"))))))
A10: CR-MAR — mardi 21h30-22h30 · B50 [CR-MAR] | B10: =IFERROR(MID($A10,FIND("[",$A10)+1,FIND("]",$A10)-FIND("[",$A10)-1),"") | C10: 46266 | D10: L2 | E10: Cyrille HANNOU [P009] | F10: =IFERROR(MID($E10,FIND("[",$E10)+1,FIND("]",$E10)-FIND("[",$E10)-1),"") | G10: =IFERROR(INDEX(Personnes!$B$5:$B$153,MATCH($F10,Personnes!$A$5:$A$153,0))&"","") | H10: =IFERROR(INDEX(Personnes!$C$5:$C$153,MATCH($F10,Personnes!$A$5:$A$153,0))&"","") | I10: 1 | K10: =IF($A10="","",IF($B10="","créneau non reconnu",IF($C10="","date d’effet manquante",IF($D10="","groupe manquant",IF(COUNTIFS($B$5:$B$80,$B10,$C$5:$C$80,$C10,$D$5:$D$80,$D10,$F$5:$F$80,$F10)>1,"doublon créneau/date/groupe/encadrant",IF($F10="","encadrant à désigner","ok"))))))
A11: CR-MAR — mardi 21h30-22h30 · B50 [CR-MAR] | B11: =IFERROR(MID($A11,FIND("[",$A11)+1,FIND("]",$A11)-FIND("[",$A11)-1),"") | C11: 46266 | D11: L2 | E11: Nelly JACQUEMOT [P024] | F11: =IFERROR(MID($E11,FIND("[",$E11)+1,FIND("]",$E11)-FIND("[",$E11)-1),"") | G11: =IFERROR(INDEX(Personnes!$B$5:$B$153,MATCH($F11,Personnes!$A$5:$A$153,0))&"","") | H11: =IFERROR(INDEX(Personnes!$C$5:$C$153,MATCH($F11,Personnes!$A$5:$A$153,0))&"","") | I11: 1 | K11: =IF($A11="","",IF($B11="","créneau non reconnu",IF($C11="","date d’effet manquante",IF($D11="","groupe manquant",IF(COUNTIFS($B$5:$B$80,$B11,$C$5:$C$80,$C11,$D$5:$D$80,$D11,$F$5:$F$80,$F11)>1,"doublon créneau/date/groupe/encadrant",IF($F11="","encadrant à désigner","ok"))))))
A12: CR-MAR — mardi 21h30-22h30 · B50 [CR-MAR] | B12: =IFERROR(MID($A12,FIND("[",$A12)+1,FIND("]",$A12)-FIND("[",$A12)-1),"") | C12: 46266 | D12: L3 | E12: Sandry [P036] | F12: =IFERROR(MID($E12,FIND("[",$E12)+1,FIND("]",$E12)-FIND("[",$E12)-1),"") | G12: =IFERROR(INDEX(Personnes!$B$5:$B$153,MATCH($F12,Personnes!$A$5:$A$153,0))&"","") | H12: =IFERROR(INDEX(Personnes!$C$5:$C$153,MATCH($F12,Personnes!$A$5:$A$153,0))&"","") | I12: 1 | K12: =IF($A12="","",IF($B12="","créneau non reconnu",IF($C12="","date d’effet manquante",IF($D12="","groupe manquant",IF(COUNTIFS($B$5:$B$80,$B12,$C$5:$C$80,$C12,$D$5:$D$80,$D12,$F$5:$F$80,$F12)>1,"doublon créneau/date/groupe/encadrant",IF($F12="","encadrant à désigner","ok"))))))
A13: CR-MAR — mardi 21h30-22h30 · B50 [CR-MAR] | B13: =IFERROR(MID($A13,FIND("[",$A13)+1,FIND("]",$A13)-FIND("[",$A13)-1),"") | C13: 46266 | D13: L4 | E13: Philippe F [P039] | F13: =IFERROR(MID($E13,FIND("[",$E13)+1,FIND("]",$E13)-FIND("[",$E13)-1),"") | G13: =IFERROR(INDEX(Personnes!$B$5:$B$153,MATCH($F13,Personnes!$A$5:$A$153,0))&"","") | H13: =IFERROR(INDEX(Personnes!$C$5:$C$153,MATCH($F13,Personnes!$A$5:$A$153,0))&"","") | I13: 1 | K13: =IF($A13="","",IF($B13="","créneau non reconnu",IF($C13="","date d’effet manquante",IF($D13="","groupe manquant",IF(COUNTIFS($B$5:$B$80,$B13,$C$5:$C$80,$C13,$D$5:$D$80,$D13,$F$5:$F$80,$F13)>1,"doublon créneau/date/groupe/encadrant",IF($F13="","encadrant à désigner","ok"))))))
A14: CR-MAR — mardi 21h30-22h30 · B50 [CR-MAR] | B14: =IFERROR(MID($A14,FIND("[",$A14)+1,FIND("]",$A14)-FIND("[",$A14)-1),"") | C14: 46266 | D14: L4 | E14: Anthony [P040] | F14: =IFERROR(MID($E14,FIND("[",$E14)+1,FIND("]",$E14)-FIND("[",$E14)-1),"") | G14: =IFERROR(INDEX(Personnes!$B$5:$B$153,MATCH($F14,Personnes!$A$5:$A$153,0))&"","") | H14: =IFERROR(INDEX(Personnes!$C$5:$C$153,MATCH($F14,Personnes!$A$5:$A$153,0))&"","") | I14: 1 | K14: =IF($A14="","",IF($B14="","créneau non reconnu",IF($C14="","date d’effet manquante",IF($D14="","groupe manquant",IF(COUNTIFS($B$5:$B$80,$B14,$C$5:$C$80,$C14,$D$5:$D$80,$D14,$F$5:$F$80,$F14)>1,"doublon créneau/date/groupe/encadrant",IF($F14="","encadrant à désigner","ok"))))))
A15: CR-MER — mercredi 21h30-22h30 · B50 [CR-MER] | B15: =IFERROR(MID($A15,FIND("[",$A15)+1,FIND("]",$A15)-FIND("[",$A15)-1),"") | C15: 46266 | D15: DNF | E15: Benjamin [P005] | F15: =IFERROR(MID($E15,FIND("[",$E15)+1,FIND("]",$E15)-FIND("[",$E15)-1),"") | G15: =IFERROR(INDEX(Personnes!$B$5:$B$153,MATCH($F15,Personnes!$A$5:$A$153,0))&"","") | H15: =IFERROR(INDEX(Personnes!$C$5:$C$153,MATCH($F15,Personnes!$A$5:$A$153,0))&"","") | I15: 1 | K15: =IF($A15="","",IF($B15="","créneau non reconnu",IF($C15="","date d’effet manquante",IF($D15="","groupe manquant",IF(COUNTIFS($B$5:$B$80,$B15,$C$5:$C$80,$C15,$D$5:$D$80,$D15,$F$5:$F$80,$F15)>1,"doublon créneau/date/groupe/encadrant",IF($F15="","encadrant à désigner","ok"))))))
A16: CR-MER — mercredi 21h30-22h30 · B50 [CR-MER] | B16: =IFERROR(MID($A16,FIND("[",$A16)+1,FIND("]",$A16)-FIND("[",$A16)-1),"") | C16: 46266 | D16: DNF | E16: Yvan [P046] | F16: =IFERROR(MID($E16,FIND("[",$E16)+1,FIND("]",$E16)-FIND("[",$E16)-1),"") | G16: =IFERROR(INDEX(Personnes!$B$5:$B$153,MATCH($F16,Personnes!$A$5:$A$153,0))&"","") | H16: =IFERROR(INDEX(Personnes!$C$5:$C$153,MATCH($F16,Personnes!$A$5:$A$153,0))&"","") | I16: 1 | K16: =IF($A16="","",IF($B16="","créneau non reconnu",IF($C16="","date d’effet manquante",IF($D16="","groupe manquant",IF(COUNTIFS($B$5:$B$80,$B16,$C$5:$C$80,$C16,$D$5:$D$80,$D16,$F$5:$F$80,$F16)>1,"doublon créneau/date/groupe/encadrant",IF($F16="","encadrant à désigner","ok"))))))
... A34: CR-VEN — vendredi 21h30-22h30 · B50 [CR-VEN] | B34: =IFERROR(MID($A34,FIND("[",$A34)+1,FIND("]",$A34)-FIND("[",$A34)-1),"") | C34: 46266 | D34: STA | E34: Guillaume BOULANT [P049] | F34: =IFERROR(MID($E34,FIND("[",$E34)+1,FIND("]",$E34)-FIND("[",$E34)-1),"") | G34: =IFERROR(INDEX(Personnes!$B$5:$B$153,MATCH($F34,Personnes!$A$5:$A$153,0))&"","") | H34: =IFERROR(INDEX(Personnes!$C$5:$C$153,MATCH($F34,Personnes!$A$5:$A$153,0))&"","") | I34: 1 | K34: =IF($A34="","",IF($B34="","créneau non reconnu",IF($C34="","date d’effet manquante",IF($D34="","groupe manquant",IF(COUNTIFS($B$5:$B$80,$B34,$C$5:$C$80,$C34,$D$5:$D$80,$D34,$F$5:$F$80,$F34)>1,"doublon créneau/date/groupe/encadrant",IF($F34="","encadrant à désigner","ok"))))))
B35: =IFERROR(MID($A35,FIND("[",$A35)+1,FIND("]",$A35)-FIND("[",$A35)-1),"") | F35: =IFERROR(MID($E35,FIND("[",$E35)+1,FIND("]",$E35)-FIND("[",$E35)-1),"") | G35: =IFERROR(INDEX(Personnes!$B$5:$B$153,MATCH($F35,Personnes!$A$5:$A$153,0))&"","") | H35: =IFERROR(INDEX(Personnes!$C$5:$C$153,MATCH($F35,Personnes!$A$5:$A$153,0))&"","") | K35: =IF($A35="","",IF($B35="","créneau non reconnu",IF($C35="","date d’effet manquante",IF($D35="","groupe manquant",IF(COUNTIFS($B$5:$B$80,$B35,$C$5:$C$80,$C35,$D$5:$D$80,$D35,$F$5:$F$80,$F35)>1,"doublon créneau/date/groupe/encadrant",IF($F35="","encadrant à désigner","ok"))))))
B36: =IFERROR(MID($A36,FIND("[",$A36)+1,FIND("]",$A36)-FIND("[",$A36)-1),"") | F36: =IFERROR(MID($E36,FIND("[",$E36)+1,FIND("]",$E36)-FIND("[",$E36)-1),"") | G36: =IFERROR(INDEX(Personnes!$B$5:$B$153,MATCH($F36,Personnes!$A$5:$A$153,0))&"","") | H36: =IFERROR(INDEX(Personnes!$C$5:$C$153,MATCH($F36,Personnes!$A$5:$A$153,0))&"","") | K36: =IF($A36="","",IF($B36="","créneau non reconnu",IF($C36="","date d’effet manquante",IF($D36="","groupe manquant",IF(COUNTIFS($B$5:$B$80,$B36,$C$5:$C$80,$C36,$D$5:$D$80,$D36,$F$5:$F$80,$F36)>1,"doublon créneau/date/groupe/encadrant",IF($F36="","encadrant à désigner","ok"))))))
B37: =IFERROR(MID($A37,FIND("[",$A37)+1,FIND("]",$A37)-FIND("[",$A37)-1),"") | F37: =IFERROR(MID($E37,FIND("[",$E37)+1,FIND("]",$E37)-FIND("[",$E37)-1),"") | G37: =IFERROR(INDEX(Personnes!$B$5:$B$153,MATCH($F37,Personnes!$A$5:$A$153,0))&"","") | H37: =IFERROR(INDEX(Personnes!$C$5:$C$153,MATCH($F37,Personnes!$A$5:$A$153,0))&"","") | K37: =IF($A37="","",IF($B37="","créneau non reconnu",IF($C37="","date d’effet manquante",IF($D37="","groupe manquant",IF(COUNTIFS($B$5:$B$80,$B37,$C$5:$C$80,$C37,$D$5:$D$80,$D37,$F$5:$F$80,$F37)>1,"doublon créneau/date/groupe/encadrant",IF($F37="","encadrant à désigner","ok"))))))
B38: =IFERROR(MID($A38,FIND("[",$A38)+1,FIND("]",$A38)-FIND("[",$A38)-1),"") | F38: =IFERROR(MID($E38,FIND("[",$E38)+1,FIND("]",$E38)-FIND("[",$E38)-1),"") | G38: =IFERROR(INDEX(Personnes!$B$5:$B$153,MATCH($F38,Personnes!$A$5:$A$153,0))&"","") | H38: =IFERROR(INDEX(Personnes!$C$5:$C$153,MATCH($F38,Personnes!$A$5:$A$153,0))&"","") | K38: =IF($A38="","",IF($B38="","créneau non reconnu",IF($C38="","date d’effet manquante",IF($D38="","groupe manquant",IF(COUNTIFS($B$5:$B$80,$B38,$C$5:$C$80,$C38,$D$5:$D$80,$D38,$F$5:$F$80,$F38)>1,"doublon créneau/date/groupe/encadrant",IF($F38="","encadrant à désigner","ok"))))))
B39: =IFERROR(MID($A39,FIND("[",$A39)+1,FIND("]",$A39)-FIND("[",$A39)-1),"") | F39: =IFERROR(MID($E39,FIND("[",$E39)+1,FIND("]",$E39)-FIND("[",$E39)-1),"") | G39: =IFERROR(INDEX(Personnes!$B$5:$B$153,MATCH($F39,Personnes!$A$5:$A$153,0))&"","") | H39: =IFERROR(INDEX(Personnes!$C$5:$C$153,MATCH($F39,Personnes!$A$5:$A$153,0))&"","") | K39: =IF($A39="","",IF($B39="","créneau non reconnu",IF($C39="","date d’effet manquante",IF($D39="","groupe manquant",IF(COUNTIFS($B$5:$B$80,$B39,$C$5:$C$80,$C39,$D$5:$D$80,$D39,$F$5:$F$80,$F39)>1,"doublon créneau/date/groupe/encadrant",IF($F39="","encadrant à désigner","ok"))))))
B40: =IFERROR(MID($A40,FIND("[",$A40)+1,FIND("]",$A40)-FIND("[",$A40)-1),"") | F40: =IFERROR(MID($E40,FIND("[",$E40)+1,FIND("]",$E40)-FIND("[",$E40)-1),"") | G40: =IFERROR(INDEX(Personnes!$B$5:$B$153,MATCH($F40,Personnes!$A$5:$A$153,0))&"","") | H40: =IFERROR(INDEX(Personnes!$C$5:$C$153,MATCH($F40,Personnes!$A$5:$A$153,0))&"","") | K40: =IF($A40="","",IF($B40="","créneau non reconnu",IF($C40="","date d’effet manquante",IF($D40="","groupe manquant",IF(COUNTIFS($B$5:$B$80,$B40,$C$5:$C$80,$C40,$D$5:$D$80,$D40,$F$5:$F$80,$F40)>1,"doublon créneau/date/groupe/encadrant",IF($F40="","encadrant à désigner","ok"))))))
B41: =IFERROR(MID($A41,FIND("[",$A41)+1,FIND("]",$A41)-FIND("[",$A41)-1),"") | F41: =IFERROR(MID($E41,FIND("[",$E41)+1,FIND("]",$E41)-FIND("[",$E41)-1),"") | G41: =IFERROR(INDEX(Personnes!$B$5:$B$153,MATCH($F41,Personnes!$A$5:$A$153,0))&"","") | H41: =IFERROR(INDEX(Personnes!$C$5:$C$153,MATCH($F41,Personnes!$A$5:$A$153,0))&"","") | K41: =IF($A41="","",IF($B41="","créneau non reconnu",IF($C41="","date d’effet manquante",IF($D41="","groupe manquant",IF(COUNTIFS($B$5:$B$80,$B41,$C$5:$C$80,$C41,$D$5:$D$80,$D41,$F$5:$F$80,$F41)>1,"doublon créneau/date/groupe/encadrant",IF($F41="","encadrant à désigner","ok"))))))
B42: =IFERROR(MID($A42,FIND("[",$A42)+1,FIND("]",$A42)-FIND("[",$A42)-1),"") | F42: =IFERROR(MID($E42,FIND("[",$E42)+1,FIND("]",$E42)-FIND("[",$E42)-1),"") | G42: =IFERROR(INDEX(Personnes!$B$5:$B$153,MATCH($F42,Personnes!$A$5:$A$153,0))&"","") | H42: =IFERROR(INDEX(Personnes!$C$5:$C$153,MATCH($F42,Personnes!$A$5:$A$153,0))&"","") | K42: =IF($A42="","",IF($B42="","créneau non reconnu",IF($C42="","date d’effet manquante",IF($D42="","groupe manquant",IF(COUNTIFS($B$5:$B$80,$B42,$C$5:$C$80,$C42,$D$5:$D$80,$D42,$F$5:$F$80,$F42)>1,"doublon créneau/date/groupe/encadrant",IF($F42="","encadrant à désigner","ok"))))))
B43: =IFERROR(MID($A43,FIND("[",$A43)+1,FIND("]",$A43)-FIND("[",$A43)-1),"") | F43: =IFERROR(MID($E43,FIND("[",$E43)+1,FIND("]",$E43)-FIND("[",$E43)-1),"") | G43: =IFERROR(INDEX(Personnes!$B$5:$B$153,MATCH($F43,Personnes!$A$5:$A$153,0))&"","") | H43: =IFERROR(INDEX(Personnes!$C$5:$C$153,MATCH($F43,Personnes!$A$5:$A$153,0))&"","") | K43: =IF($A43="","",IF($B43="","créneau non reconnu",IF($C43="","date d’effet manquante",IF($D43="","groupe manquant",IF(COUNTIFS($B$5:$B$80,$B43,$C$5:$C$80,$C43,$D$5:$D$80,$D43,$F$5:$F$80,$F43)>1,"doublon créneau/date/groupe/encadrant",IF($F43="","encadrant à désigner","ok"))))))
B44: =IFERROR(MID($A44,FIND("[",$A44)+1,FIND("]",$A44)-FIND("[",$A44)-1),"") | F44: =IFERROR(MID($E44,FIND("[",$E44)+1,FIND("]",$E44)-FIND("[",$E44)-1),"") | G44: =IFERROR(INDEX(Personnes!$B$5:$B$153,MATCH($F44,Personnes!$A$5:$A$153,0))&"","") | H44: =IFERROR(INDEX(Personnes!$C$5:$C$153,MATCH($F44,Personnes!$A$5:$A$153,0))&"","") | K44: =IF($A44="","",IF($B44="","créneau non reconnu",IF($C44="","date d’effet manquante",IF($D44="","groupe manquant",IF(COUNTIFS($B$5:$B$80,$B44,$C$5:$C$80,$C44,$D$5:$D$80,$D44,$F$5:$F$80,$F44)>1,"doublon créneau/date/groupe/encadrant",IF($F44="","encadrant à désigner","ok"))))))
B45: =IFERROR(MID($A45,FIND("[",$A45)+1,FIND("]",$A45)-FIND("[",$A45)-1),"") | F45: =IFERROR(MID($E45,FIND("[",$E45)+1,FIND("]",$E45)-FIND("[",$E45)-1),"") | G45: =IFERROR(INDEX(Personnes!$B$5:$B$153,MATCH($F45,Personnes!$A$5:$A$153,0))&"","") | H45: =IFERROR(INDEX(Personnes!$C$5:$C$153,MATCH($F45,Personnes!$A$5:$A$153,0))&"","") | K45: =IF($A45="","",IF($B45="","créneau non reconnu",IF($C45="","date d’effet manquante",IF($D45="","groupe manquant",IF(COUNTIFS($B$5:$B$80,$B45,$C$5:$C$80,$C45,$D$5:$D$80,$D45,$F$5:$F$80,$F45)>1,"doublon créneau/date/groupe/encadrant",IF($F45="","encadrant à désigner","ok"))))))
B46: =IFERROR(MID($A46,FIND("[",$A46)+1,FIND("]",$A46)-FIND("[",$A46)-1),"") | F46: =IFERROR(MID($E46,FIND("[",$E46)+1,FIND("]",$E46)-FIND("[",$E46)-1),"") | G46: =IFERROR(INDEX(Personnes!$B$5:$B$153,MATCH($F46,Personnes!$A$5:$A$153,0))&"","") | H46: =IFERROR(INDEX(Personnes!$C$5:$C$153,MATCH($F46,Personnes!$A$5:$A$153,0))&"","") | K46: =IF($A46="","",IF($B46="","créneau non reconnu",IF($C46="","date d’effet manquante",IF($D46="","groupe manquant",IF(COUNTIFS($B$5:$B$80,$B46,$C$5:$C$80,$C46,$D$5:$D$80,$D46,$F$5:$F$80,$F46)>1,"doublon créneau/date/groupe/encadrant",IF($F46="","encadrant à désigner","ok"))))))
... B80: =IFERROR(MID($A80,FIND("[",$A80)+1,FIND("]",$A80)-FIND("[",$A80)-1),"") | F80: =IFERROR(MID($E80,FIND("[",$E80)+1,FIND("]",$E80)-FIND("[",$E80)-1),"") | G80: =IFERROR(INDEX(Personnes!$B$5:$B$153,MATCH($F80,Personnes!$A$5:$A$153,0))&"","") | H80: =IFERROR(INDEX(Personnes!$C$5:$C$153,MATCH($F80,Personnes!$A$5:$A$153,0))&"","") | K80: =IF($A80="","",IF($B80="","créneau non reconnu",IF($C80="","date d’effet manquante",IF($D80="","groupe manquant",IF(COUNTIFS($B$5:$B$80,$B80,$C$5:$C$80,$C80,$D$5:$D$80,$D80,$F$5:$F$80,$F80)>1,"doublon créneau/date/groupe/encadrant",IF($F80="","encadrant à désigner","ok"))))))

Sheet Personnes
A1: Personnes — référentiel unique du club
A2: Élèves et encadrants dans un seul référentiel. Les deux dernières colonnes alimentent la liste de sélection, triée par prénom.
A4: ID | B4: Nom | C4: Prénom | D4: Genre | E4: Date de naissance | F4: Courriel | G4: Statut | H4: Origine de la donnée | I4: Commentaire | J4: Libellé (calculé) | K4: Rang par prénom (calculé)
A5: P100 | B5: AUBERT | C5: Sebastien | G5: actif | H5: Organisation des lignes 2026-2027 (transmis 05/09/2026, complement 06/09/2026) | J5: =IF($A5="","",TRIM(IF($C5="",$B5,$C5&" "&$B5))&" ["&$A5&"]") | K5: =IF($A5="","",COUNTIF(Personnes!$C$5:$C$104,"<"&$C5)+COUNTIF($C$5:$C5,$C5))
A6: P053 | B6: BACHA | C6: Achour | G6: actif | H6: Planning encadrement 2026-27, groupe Stagiaire | I6: Prénom seul ou surnom : nom de famille à compléter | J6: =IF($A6="","",TRIM(IF($C6="",$B6,$C6&" "&$B6))&" ["&$A6&"]") | K6: =IF($A6="","",COUNTIF(Personnes!$C$5:$C$104,"<"&$C6)+COUNTIF($C$5:$C6,$C6))
A7: P003 | B7: BARBIER | C7: Aurelien | G7: actif | H7: Classeur Suivi Apnéistes L3 2025-2026 | J7: =IF($A7="","",TRIM(IF($C7="",$B7,$C7&" "&$B7))&" ["&$A7&"]") | K7: =IF($A7="","",COUNTIF(Personnes!$C$5:$C$104,"<"&$C7)+COUNTIF($C$5:$C7,$C7))
A8: P076 | B8: BAUTISTA | C8: Mary | G8: actif | H8: Organisation des lignes 2026-2027 (transmis 05/09/2026, complement 06/09/2026) | J8: =IF($A8="","",TRIM(IF($C8="",$B8,$C8&" "&$B8))&" ["&$A8&"]") | K8: =IF($A8="","",COUNTIF(Personnes!$C$5:$C$104,"<"&$C8)+COUNTIF($C$5:$C8,$C8))
A9: P030 | B9: BEAUVALLET | C9: Dominique | F9: dombeauvallet@free.fr | G9: actif | H9: Planning encadrement 2026-27, groupe L1 | I9: dit Dom | J9: =IF($A9="","",TRIM(IF($C9="",$B9,$C9&" "&$B9))&" ["&$A9&"]") | K9: =IF($A9="","",COUNTIF(Personnes!$C$5:$C$104,"<"&$C9)+COUNTIF($C$5:$C9,$C9))
A10: P019 | B10: BECHARA | C10: Lionel | G10: actif | H10: Classeur Suivi Apnéistes L3 2025-2026 | J10: =IF($A10="","",TRIM(IF($C10="",$B10,$C10&" "&$B10))&" ["&$A10&"]") | K10: =IF($A10="","",COUNTIF(Personnes!$C$5:$C$104,"<"&$C10)+COUNTIF($C$5:$C10,$C10))
A11: P101 | B11: BELHADJ KACEM | C11: Mohammed | G11: actif | H11: Organisation des lignes 2026-2027 (transmis 05/09/2026, complement 06/09/2026) | J11: =IF($A11="","",TRIM(IF($C11="",$B11,$C11&" "&$B11))&" ["&$A11&"]") | K11: =IF($A11="","",COUNTIF(Personnes!$C$5:$C$104,"<"&$C11)+COUNTIF($C$5:$C11,$C11))
A12: P077 | B12: BENDER | C12: Marc | G12: actif | H12: Organisation des lignes 2026-2027 (transmis 05/09/2026, complement 06/09/2026) | J12: =IF($A12="","",TRIM(IF($C12="",$B12,$C12&" "&$B12))&" ["&$A12&"]") | K12: =IF($A12="","",COUNTIF(Personnes!$C$5:$C$104,"<"&$C12)+COUNTIF($C$5:$C12,$C12))
A13: P055 | B13: BENMANSOUR | C13: Ouafa | F13: Amiwafa77@yahoo.fr | G13: actif | H13: Planning encadrement 2026-27, groupe — | I13: Prénom seul ou surnom : nom de famille à compléter | J13: =IF($A13="","",TRIM(IF($C13="",$B13,$C13&" "&$B13))&" ["&$A13&"]") | K13: =IF($A13="","",COUNTIF(Personnes!$C$5:$C$104,"<"&$C13)+COUNTIF($C$5:$C13,$C13))
A14: P035 | B14: BEYL | C14: Gabrielle | F14: g.beyl@outlook.fr | G14: actif | H14: Planning encadrement 2026-27, groupe L3 | I14: Prénom seul ou surnom : nom de famille à compléter | J14: =IF($A14="","",TRIM(IF($C14="",$B14,$C14&" "&$B14))&" ["&$A14&"]") | K14: =IF($A14="","",COUNTIF(Personnes!$C$5:$C$104,"<"&$C14)+COUNTIF($C$5:$C14,$C14))
A15: P078 | B15: BEZICOT | C15: Patrick | G15: actif | H15: Organisation des lignes 2026-2027 (transmis 05/09/2026, complement 06/09/2026) | J15: =IF($A15="","",TRIM(IF($C15="",$B15,$C15&" "&$B15))&" ["&$A15&"]") | K15: =IF($A15="","",COUNTIF(Personnes!$C$5:$C$104,"<"&$C15)+COUNTIF($C$5:$C15,$C15))
A16: P079 | B16: BIZON | C16: Christophe | G16: actif | H16: Organisation des lignes 2026-2027 (transmis 05/09/2026, complement 06/09/2026) | J16: =IF($A16="","",TRIM(IF($C16="",$B16,$C16&" "&$B16))&" ["&$A16&"]") | K16: =IF($A16="","",COUNTIF(Personnes!$C$5:$C$104,"<"&$C16)+COUNTIF($C$5:$C16,$C16))
A17: P060 | B17: BOUGEROL | C17: Bruno | F17: b_bougerol@yahoo.fr | G17: actif | H17: Planning encadrement 2026-27, groupe — | I17: Prénom seul ou surnom : nom de famille à compléter | J17: =IF($A17="","",TRIM(IF($C17="",$B17,$C17&" "&$B17))&" ["&$A17&"]") | K17: =IF($A17="","",COUNTIF(Personnes!$C$5:$C$104,"<"&$C17)+COUNTIF($C$5:$C17,$C17))
A18: P068 | B18: BOUHAMMOU | C18: Salman | G18: actif | H18: Organisation des lignes 2026-2027 (Craft.me, transmis 05/09/2026) | J18: =IF($A18="","",TRIM(IF($C18="",$B18,$C18&" "&$B18))&" ["&$A18&"]") | K18: =IF($A18="","",COUNTIF(Personnes!$C$5:$C$104,"<"&$C18)+COUNTIF($C$5:$C18,$C18))
A19: P049 | B19: BOULANT | C19: Guillaume | F19: gboulant@gmail.com | G19: actif | H19: Planning encadrement 2026-27, groupe STA 2 | I19: Prénom seul ou surnom : nom de famille à compléter | J19: =IF($A19="","",TRIM(IF($C19="",$B19,$C19&" "&$B19))&" ["&$A19&"]") | K19: =IF($A19="","",COUNTIF(Personnes!$C$5:$C$104,"<"&$C19)+COUNTIF($C$5:$C19,$C19))
A20: P080 | B20: BRIAULT | C20: Beverly | G20: actif | H20: Organisation des lignes 2026-2027 (transmis 05/09/2026, complement 06/09/2026) | J20: =IF($A20="","",TRIM(IF($C20="",$B20,$C20&" "&$B20))&" ["&$A20&"]") | K20: =IF($A20="","",COUNTIF(Personnes!$C$5:$C$104,"<"&$C20)+COUNTIF($C$5:$C20,$C20))
A21: P056 | B21: BRIDENNE | C21: Philippe | F21: philippe.bridenne@gmail.com | G21: actif | H21: Planning encadrement 2026-27, groupe — | I21: Prénom seul ou surnom : nom de famille à compléter | J21: =IF($A21="","",TRIM(IF($C21="",$B21,$C21&" "&$B21))&" ["&$A21&"]") | K21: =IF($A21="","",COUNTIF(Personnes!$C$5:$C$104,"<"&$C21)+COUNTIF($C$5:$C21,$C21))
A22: P081 | B22: CATHALA | C22: Virginie | G22: actif | H22: Organisation des lignes 2026-2027 (transmis 05/09/2026, complement 06/09/2026) | J22: =IF($A22="","",TRIM(IF($C22="",$B22,$C22&" "&$B22))&" ["&$A22&"]") | K22: =IF($A22="","",COUNTIF(Personnes!$C$5:$C$104,"<"&$C22)+COUNTIF($C$5:$C22,$C22))
A23: P069 | B23: CAVATORE | C23: Magali | G23: actif | H23: Organisation des lignes 2026-2027 (Craft.me, transmis 05/09/2026) | J23: =IF($A23="","",TRIM(IF($C23="",$B23,$C23&" "&$B23))&" ["&$A23&"]") | K23: =IF($A23="","",COUNTIF(Personnes!$C$5:$C$104,"<"&$C23)+COUNTIF($C$5:$C23,$C23))
A24: P097 | B24: CHABERNAUD | C24: Christophe | G24: actif | H24: Organisation des lignes 2026-2027 (transmis 05/09/2026, complement 06/09/2026) | J24: =IF($A24="","",TRIM(IF($C24="",$B24,$C24&" "&$B24))&" ["&$A24&"]") | K24: =IF($A24="","",COUNTIF(Personnes!$C$5:$C$104,"<"&$C24)+COUNTIF($C$5:$C24,$C24))
A25: P031 | B25: CHARDONNET | C25: Victorinne | F25: chardonnetvictorine@gmail.com | G25: actif | H25: Planning encadrement 2026-27, groupe L1 | I25: Prénom seul ou surnom : nom de famille à compléter | J25: =IF($A25="","",TRIM(IF($C25="",$B25,$C25&" "&$B25))&" ["&$A25&"]") | K25: =IF($A25="","",COUNTIF(Personnes!$C$5:$C$104,"<"&$C25)+COUNTIF($C$5:$C25,$C25))
A26: P022 | B26: CHIARAMONTE | C26: Matthieu | G26: actif | H26: Classeur Suivi Apnéistes L3 2025-2026 | J26: =IF($A26="","",TRIM(IF($C26="",$B26,$C26&" "&$B26))&" ["&$A26&"]") | K26: =IF($A26="","",COUNTIF(Personnes!$C$5:$C$104,"<"&$C26)+COUNTIF($C$5:$C26,$C26))
A27: P082 | B27: CODAZZO | C27: Franco | G27: actif | H27: Organisation des lignes 2026-2027 (transmis 05/09/2026, complement 06/09/2026) | J27: =IF($A27="","",TRIM(IF($C27="",$B27,$C27&" "&$B27))&" ["&$A27&"]") | K27: =IF($A27="","",COUNTIF(Personnes!$C$5:$C$104,"<"&$C27)+COUNTIF($C$5:$C27,$C27))
A28: P006 | B28: COLIN DE VERDIERE | C28: Caroline | F28: treso.apneeattitude@outlook.com | G28: actif | H28: Classeur Suivi Apnéistes L3 2025-2026 | J28: =IF($A28="","",TRIM(IF($C28="",$B28,$C28&" "&$B28))&" ["&$A28&"]") | K28: =IF($A28="","",COUNTIF(Personnes!$C$5:$C$104,"<"&$C28)+COUNTIF($C$5:$C28,$C28))
A29: P011 | B29: COLIN DE VERDIERE | C29: Etienne | F29: e.cdv@free.fr | G29: actif | H29: Classeur Suivi Apnéistes L3 2025-2026 | J29: =IF($A29="","",TRIM(IF($C29="",$B29,$C29&" "&$B29))&" ["&$A29&"]") | K29: =IF($A29="","",COUNTIF(Personnes!$C$5:$C$104,"<"&$C29)+COUNTIF($C$5:$C29,$C29))
A30: P057 | B30: COLIN DE VERDIERE | C30: Antoine | F30: antoinecdv@gmail.com | G30: actif | H30: Planning encadrement 2026-27, groupe — | I30: Prénom seul ou surnom : nom de famille à compléter | J30: =IF($A30="","",TRIM(IF($C30="",$B30,$C30&" "&$B30))&" ["&$A30&"]") | K30: =IF($A30="","",COUNTIF(Personnes!$C$5:$C$104,"<"&$C30)+COUNTIF($C$5:$C30,$C30))
A31: P063 | B31: COLLINET | C31: Sabine | F31: sabine.collinet@gmail.com | G31: actif | H31: Planning encadrement 2026-27, groupe — | I31: Prénom seul ou surnom : nom de famille à compléter | J31: =IF($A31="","",TRIM(IF($C31="",$B31,$C31&" "&$B31))&" ["&$A31&"]") | K31: =IF($A31="","",COUNTIF(Personnes!$C$5:$C$104,"<"&$C31)+COUNTIF($C$5:$C31,$C31))
A32: P083 | B32: CORNET-VERNET | C32: Sandra | G32: actif | H32: Organisation des lignes 2026-2027 (transmis 05/09/2026, complement 06/09/2026) | J32: =IF($A32="","",TRIM(IF($C32="",$B32,$C32&" "&$B32))&" ["&$A32&"]") | K32: =IF($A32="","",COUNTIF(Personnes!$C$5:$C$104,"<"&$C32)+COUNTIF($C$5:$C32,$C32))
A33: P084 | B33: COSSAIS | C33: Monia | G33: actif | H33: Organisation des lignes 2026-2027 (transmis 05/09/2026, complement 06/09/2026) | J33: =IF($A33="","",TRIM(IF($C33="",$B33,$C33&" "&$B33))&" ["&$A33&"]") | K33: =IF($A33="","",COUNTIF(Personnes!$C$5:$C$104,"<"&$C33)+COUNTIF($C$5:$C33,$C33))
A34: P007 | B34: DANSEUX | C34: Charline | F34: charline.danseux@gmail.com | G34: actif | H34: Classeur Suivi Apnéistes L3 2025-2026 | J34: =IF($A34="","",TRIM(IF($C34="",$B34,$C34&" "&$B34))&" ["&$A34&"]") | K34: =IF($A34="","",COUNTIF(Personnes!$C$5:$C$104,"<"&$C34)+COUNTIF($C$5:$C34,$C34))
A35: P085 | B35: DE LA BRETESCHE | C35: Arnaud | G35: actif | H35: Organisation des lignes 2026-2027 (transmis 05/09/2026, complement 06/09/2026) | J35: =IF($A35="","",TRIM(IF($C35="",$B35,$C35&" "&$B35))&" ["&$A35&"]") | K35: =IF($A35="","",COUNTIF(Personnes!$C$5:$C$104,"<"&$C35)+COUNTIF($C$5:$C35,$C35))
A36: P086 | B36: DEPRETZ | C36: Alain | G36: actif | H36: Organisation des lignes 2026-2027 (transmis 05/09/2026, complement 06/09/2026) | J36: =IF($A36="","",TRIM(IF($C36="",$B36,$C36&" "&$B36))&" ["&$A36&"]") | K36: =IF($A36="","",COUNTIF(Personnes!$C$5:$C$104,"<"&$C36)+COUNTIF($C$5:$C36,$C36))
A37: P002 | B37: DESMERGES | C37: Antonin | G37: actif | H37: Classeur Suivi Apnéistes L3 2025-2026 | J37: =IF($A37="","",TRIM(IF($C37="",$B37,$C37&" "&$B37))&" ["&$A37&"]") | K37: =IF($A37="","",COUNTIF(Personnes!$C$5:$C$104,"<"&$C37)+COUNTIF($C$5:$C37,$C37))
A38: P070 | B38: DEVILLIERS | C38: Aurélien | G38: actif | H38: Organisation des lignes 2026-2027 (Craft.me, transmis 05/09/2026) | J38: =IF($A38="","",TRIM(IF($C38="",$B38,$C38&" "&$B38))&" ["&$A38&"]") | K38: =IF($A38="","",COUNTIF(Personnes!$C$5:$C$104,"<"&$C38)+COUNTIF($C$5:$C38,$C38))
A39: P087 | B39: DUBUISSON | C39: Céline | G39: actif | H39: Organisation des lignes 2026-2027 (transmis 05/09/2026, complement 06/09/2026) | J39: =IF($A39="","",TRIM(IF($C39="",$B39,$C39&" "&$B39))&" ["&$A39&"]") | K39: =IF($A39="","",COUNTIF(Personnes!$C$5:$C$104,"<"&$C39)+COUNTIF($C$5:$C39,$C39))
A40: P043 | B40: DUMONT | C40: Céline | F40: celibouteiller@gmail.com | G40: actif | H40: Planning encadrement 2026-27, groupe L4 | I40: Prénom seul ou surnom : nom de famille à compléter | J40: =IF($A40="","",TRIM(IF($C40="",$B40,$C40&" "&$B40))&" ["&$A40&"]") | K40: =IF($A40="","",COUNTIF(Personnes!$C$5:$C$104,"<"&$C40)+COUNTIF($C$5:$C40,$C40))
A41: P102 | B41: DUSSAUD | C41: Sebastien | G41: actif | H41: Organisation des lignes 2026-2027 (transmis 05/09/2026, complement 06/09/2026) | J41: =IF($A41="","",TRIM(IF($C41="",$B41,$C41&" "&$B41))&" ["&$A41&"]") | K41: =IF($A41="","",COUNTIF(Personnes!$C$5:$C$104,"<"&$C41)+COUNTIF($C$5:$C41,$C41))
...

Sheet Qualifications_Personnes
A1: Qualifications détenues
A2: Sélectionnez la personne : l'identifiant, le nom et le prénom se remplissent tout seuls.
A4: Sélection par nom ou prénom | B4: Personne (ID) | C4: Nom | D4: Prénom | E4: Qualification | F4: Type (calculé) | G4: Libellé (calculé) | H4: Date d'obtention | I4: Date de recyclage | J4: Valide | K4: Commentaire
B5: =IFERROR(MID($A5,FIND("[",$A5)+1,FIND("]",$A5)-FIND("[",$A5)-1),"") | C5: =IFERROR(INDEX(Personnes!$B$5:$B$153,MATCH($B5,Personnes!$A$5:$A$153,0))&"","") | D5: =IFERROR(INDEX(Personnes!$C$5:$C$153,MATCH($B5,Personnes!$A$5:$A$153,0))&"","") | F5: =IFERROR(INDEX(Referentiels!$C$66:$C$76,MATCH($E5,Referentiels!$A$66:$A$76,0))&"","") | G5: =IFERROR(INDEX(Referentiels!$B$66:$B$76,MATCH($E5,Referentiels!$A$66:$A$76,0))&"","")
B6: =IFERROR(MID($A6,FIND("[",$A6)+1,FIND("]",$A6)-FIND("[",$A6)-1),"") | C6: =IFERROR(INDEX(Personnes!$B$5:$B$153,MATCH($B6,Personnes!$A$5:$A$153,0))&"","") | D6: =IFERROR(INDEX(Personnes!$C$5:$C$153,MATCH($B6,Personnes!$A$5:$A$153,0))&"","") | F6: =IFERROR(INDEX(Referentiels!$C$66:$C$76,MATCH($E6,Referentiels!$A$66:$A$76,0))&"","") | G6: =IFERROR(INDEX(Referentiels!$B$66:$B$76,MATCH($E6,Referentiels!$A$66:$A$76,0))&"","")
B7: =IFERROR(MID($A7,FIND("[",$A7)+1,FIND("]",$A7)-FIND("[",$A7)-1),"") | C7: =IFERROR(INDEX(Personnes!$B$5:$B$153,MATCH($B7,Personnes!$A$5:$A$153,0))&"","") | D7: =IFERROR(INDEX(Personnes!$C$5:$C$153,MATCH($B7,Personnes!$A$5:$A$153,0))&"","") | F7: =IFERROR(INDEX(Referentiels!$C$66:$C$76,MATCH($E7,Referentiels!$A$66:$A$76,0))&"","") | G7: =IFERROR(INDEX(Referentiels!$B$66:$B$76,MATCH($E7,Referentiels!$A$66:$A$76,0))&"","")
B8: =IFERROR(MID($A8,FIND("[",$A8)+1,FIND("]",$A8)-FIND("[",$A8)-1),"") | C8: =IFERROR(INDEX(Personnes!$B$5:$B$153,MATCH($B8,Personnes!$A$5:$A$153,0))&"","") | D8: =IFERROR(INDEX(Personnes!$C$5:$C$153,MATCH($B8,Personnes!$A$5:$A$153,0))&"","") | F8: =IFERROR(INDEX(Referentiels!$C$66:$C$76,MATCH($E8,Referentiels!$A$66:$A$76,0))&"","") | G8: =IFERROR(INDEX(Referentiels!$B$66:$B$76,MATCH($E8,Referentiels!$A$66:$A$76,0))&"","")
B9: =IFERROR(MID($A9,FIND("[",$A9)+1,FIND("]",$A9)-FIND("[",$A9)-1),"") | C9: =IFERROR(INDEX(Personnes!$B$5:$B$153,MATCH($B9,Personnes!$A$5:$A$153,0))&"","") | D9: =IFERROR(INDEX(Personnes!$C$5:$C$153,MATCH($B9,Personnes!$A$5:$A$153,0))&"","") | F9: =IFERROR(INDEX(Referentiels!$C$66:$C$76,MATCH($E9,Referentiels!$A$66:$A$76,0))&"","") | G9: =IFERROR(INDEX(Referentiels!$B$66:$B$76,MATCH($E9,Referentiels!$A$66:$A$76,0))&"","")
B10: =IFERROR(MID($A10,FIND("[",$A10)+1,FIND("]",$A10)-FIND("[",$A10)-1),"") | C10: =IFERROR(INDEX(Personnes!$B$5:$B$153,MATCH($B10,Personnes!$A$5:$A$153,0))&"","") | D10: =IFERROR(INDEX(Personnes!$C$5:$C$153,MATCH($B10,Personnes!$A$5:$A$153,0))&"","") | F10: =IFERROR(INDEX(Referentiels!$C$66:$C$76,MATCH($E10,Referentiels!$A$66:$A$76,0))&"","") | G10: =IFERROR(INDEX(Referentiels!$B$66:$B$76,MATCH($E10,Referentiels!$A$66:$A$76,0))&"","")
B11: =IFERROR(MID($A11,FIND("[",$A11)+1,FIND("]",$A11)-FIND("[",$A11)-1),"") | C11: =IFERROR(INDEX(Personnes!$B$5:$B$153,MATCH($B11,Personnes!$A$5:$A$153,0))&"","") | D11: =IFERROR(INDEX(Personnes!$C$5:$C$153,MATCH($B11,Personnes!$A$5:$A$153,0))&"","") | F11: =IFERROR(INDEX(Referentiels!$C$66:$C$76,MATCH($E11,Referentiels!$A$66:$A$76,0))&"","") | G11: =IFERROR(INDEX(Referentiels!$B$66:$B$76,MATCH($E11,Referentiels!$A$66:$A$76,0))&"","")
B12: =IFERROR(MID($A12,FIND("[",$A12)+1,FIND("]",$A12)-FIND("[",$A12)-1),"") | C12: =IFERROR(INDEX(Personnes!$B$5:$B$153,MATCH($B12,Personnes!$A$5:$A$153,0))&"","") | D12: =IFERROR(INDEX(Personnes!$C$5:$C$153,MATCH($B12,Personnes!$A$5:$A$153,0))&"","") | F12: =IFERROR(INDEX(Referentiels!$C$66:$C$76,MATCH($E12,Referentiels!$A$66:$A$76,0))&"","") | G12: =IFERROR(INDEX(Referentiels!$B$66:$B$76,MATCH($E12,Referentiels!$A$66:$A$76,0))&"","")
B13: =IFERROR(MID($A13,FIND("[",$A13)+1,FIND("]",$A13)-FIND("[",$A13)-1),"") | C13: =IFERROR(INDEX(Personnes!$B$5:$B$153,MATCH($B13,Personnes!$A$5:$A$153,0))&"","") | D13: =IFERROR(INDEX(Personnes!$C$5:$C$153,MATCH($B13,Personnes!$A$5:$A$153,0))&"","") | F13: =IFERROR(INDEX(Referentiels!$C$66:$C$76,MATCH($E13,Referentiels!$A$66:$A$76,0))&"","") | G13: =IFERROR(INDEX(Referentiels!$B$66:$B$76,MATCH($E13,Referentiels!$A$66:$A$76,0))&"","")
B14: =IFERROR(MID($A14,FIND("[",$A14)+1,FIND("]",$A14)-FIND("[",$A14)-1),"") | C14: =IFERROR(INDEX(Personnes!$B$5:$B$153,MATCH($B14,Personnes!$A$5:$A$153,0))&"","") | D14: =IFERROR(INDEX(Personnes!$C$5:$C$153,MATCH($B14,Personnes!$A$5:$A$153,0))&"","") | F14: =IFERROR(INDEX(Referentiels!$C$66:$C$76,MATCH($E14,Referentiels!$A$66:$A$76,0))&"","") | G14: =IFERROR(INDEX(Referentiels!$B$66:$B$76,MATCH($E14,Referentiels!$A$66:$A$76,0))&"","")
B15: =IFERROR(MID($A15,FIND("[",$A15)+1,FIND("]",$A15)-FIND("[",$A15)-1),"") | C15: =IFERROR(INDEX(Personnes!$B$5:$B$153,MATCH($B15,Personnes!$A$5:$A$153,0))&"","") | D15: =IFERROR(INDEX(Personnes!$C$5:$C$153,MATCH($B15,Personnes!$A$5:$A$153,0))&"","") | F15: =IFERROR(INDEX(Referentiels!$C$66:$C$76,MATCH($E15,Referentiels!$A$66:$A$76,0))&"","") | G15: =IFERROR(INDEX(Referentiels!$B$66:$B$76,MATCH($E15,Referentiels!$A$66:$A$76,0))&"","")
B16: =IFERROR(MID($A16,FIND("[",$A16)+1,FIND("]",$A16)-FIND("[",$A16)-1),"") | C16: =IFERROR(INDEX(Personnes!$B$5:$B$153,MATCH($B16,Personnes!$A$5:$A$153,0))&"","") | D16: =IFERROR(INDEX(Personnes!$C$5:$C$153,MATCH($B16,Personnes!$A$5:$A$153,0))&"","") | F16: =IFERROR(INDEX(Referentiels!$C$66:$C$76,MATCH($E16,Referentiels!$A$66:$A$76,0))&"","") | G16: =IFERROR(INDEX(Referentiels!$B$66:$B$76,MATCH($E16,Referentiels!$A$66:$A$76,0))&"","")
... B200: =IFERROR(MID($A200,FIND("[",$A200)+1,FIND("]",$A200)-FIND("[",$A200)-1),"") | C200: =IFERROR(INDEX(Personnes!$B$5:$B$153,MATCH($B200,Personnes!$A$5:$A$153,0))&"","") | D200: =IFERROR(INDEX(Personnes!$C$5:$C$153,MATCH($B200,Personnes!$A$5:$A$153,0))&"","") | F200: =IFERROR(INDEX(Referentiels!$C$66:$C$76,MATCH($E200,Referentiels!$A$66:$A$76,0))&"","") | G200: =IFERROR(INDEX(Referentiels!$B$66:$B$76,MATCH($E200,Referentiels!$A$66:$A$76,0))&"","")

Sheet Inscriptions
A1: Inscriptions de la saison
A2: La colonne Contrôle signale les doublons et les informations manquantes.
A4: Saison | B4: Sélection par nom ou prénom | C4: Personne (ID) | D4: Nom | E4: Prénom | F4: Groupe de niveau | G4: Rôle | H4: Support de saisie | I4: Date de début | J4: Date de fin | K4: Objectif de la saison | L4: Commentaire | M4: Contrôle
A5: 2026-2027 | B5: Dominique BEAUVALLET [P030] | C5: =IFERROR(MID($B5,FIND("[",$B5)+1,FIND("]",$B5)-FIND("[",$B5)-1),"") | D5: =IFERROR(INDEX(Personnes!$B$5:$B$153,MATCH($C5,Personnes!$A$5:$A$153,0))&"","") | E5: =IFERROR(INDEX(Personnes!$C$5:$C$153,MATCH($C5,Personnes!$A$5:$A$153,0))&"","") | F5: L1 | G5: encadrant | H5: classeur | I5: 46272 | M5: =IF($B5="","",IF($C5="","personne non reconnue",IF(ISERROR(SEARCH(TRIM($E5&" "&$D5),$B5)),"libellé incohérent avec l’identifiant",IF(COUNTIFS($A$5:$A$500,$A5,$C$5:$C$500,$C5,$F$5:$F$500,$F5,$G$5:$G$500,$G5)>1,"doublon",IF($F5="","groupe manquant",IF($G5="","rôle manquant",IF($H5="","support de saisie manquant",IF(AND($I5<>"",$J5<>"",$J5<$I5),"date de fin antérieure à la date de début",IF(AND($G5="encadrant",IFERROR(INDEX(Personnes!$F$5:$F$153,MATCH($C5,Personnes!$A$5:$A$153,0)),"")=""),"courriel encadrant manquant","ok")))))))))
A6: 2026-2027 | B6: Victorinne CHARDONNET [P031] | C6: =IFERROR(MID($B6,FIND("[",$B6)+1,FIND("]",$B6)-FIND("[",$B6)-1),"") | D6: =IFERROR(INDEX(Personnes!$B$5:$B$153,MATCH($C6,Personnes!$A$5:$A$153,0))&"","") | E6: =IFERROR(INDEX(Personnes!$C$5:$C$153,MATCH($C6,Personnes!$A$5:$A$153,0))&"","") | F6: L1 | G6: encadrant | H6: classeur | I6: 46272 | M6: =IF($B6="","",IF($C6="","personne non reconnue",IF(ISERROR(SEARCH(TRIM($E6&" "&$D6),$B6)),"libellé incohérent avec l’identifiant",IF(COUNTIFS($A$5:$A$500,$A6,$C$5:$C$500,$C6,$F$5:$F$500,$F6,$G$5:$G$500,$G6)>1,"doublon",IF($F6="","groupe manquant",IF($G6="","rôle manquant",IF($H6="","support de saisie manquant",IF(AND($I6<>"",$J6<>"",$J6<$I6),"date de fin antérieure à la date de début",IF(AND($G6="encadrant",IFERROR(INDEX(Personnes!$F$5:$F$153,MATCH($C6,Personnes!$A$5:$A$153,0)),"")=""),"courriel encadrant manquant","ok")))))))))
A7: 2026-2027 | B7: Michael GRENIER [P032] | C7: =IFERROR(MID($B7,FIND("[",$B7)+1,FIND("]",$B7)-FIND("[",$B7)-1),"") | D7: =IFERROR(INDEX(Personnes!$B$5:$B$153,MATCH($C7,Personnes!$A$5:$A$153,0))&"","") | E7: =IFERROR(INDEX(Personnes!$C$5:$C$153,MATCH($C7,Personnes!$A$5:$A$153,0))&"","") | F7: L1 | G7: encadrant | H7: classeur | I7: 46272 | M7: =IF($B7="","",IF($C7="","personne non reconnue",IF(ISERROR(SEARCH(TRIM($E7&" "&$D7),$B7)),"libellé incohérent avec l’identifiant",IF(COUNTIFS($A$5:$A$500,$A7,$C$5:$C$500,$C7,$F$5:$F$500,$F7,$G$5:$G$500,$G7)>1,"doublon",IF($F7="","groupe manquant",IF($G7="","rôle manquant",IF($H7="","support de saisie manquant",IF(AND($I7<>"",$J7<>"",$J7<$I7),"date de fin antérieure à la date de début",IF(AND($G7="encadrant",IFERROR(INDEX(Personnes!$F$5:$F$153,MATCH($C7,Personnes!$A$5:$A$153,0)),"")=""),"courriel encadrant manquant","ok")))))))))
